Workbook

Sheet JANUARI
A8: NOTA PENCAIRAN DANA (NPD)
A9: Nomor : 70/DIV-KEU/PPB/I/2026
A10: BENDAHARA PENGELUARAN
A11: PERUMDA PASAR BANJARMASIN
A12: Supaya mencairkan dana kepada
A14: 1. Sub Kegiatan | D14: : | E14: Beban Investasi
A15: 2. Nomor | D15: : | E15: 2.1.2
A16: 3. Tahun Anggaran | D16: : | E16: 2026
A17: 4. Jumlah Yang Diminta | D17: : | E17: =I48 -> 88500000
E18: =PROPER(IF(E17=0,"nol",IF(E17<0,"minus ","")&SUBSTITUTE(TRIM(SUBSTITUTE(SUBSTITUTE(SUBSTITUTE(SUBSTITUTE(SUBSTITUTE(SUBSTITUTE(SUBSTITUTE(SUBSTITUTE(SUBSTITUTE(SUBSTITUTE(SUBSTITUTE(SUBSTITUTE(SUBSTITUTE(SUBSTITUTE(SUBSTITUTE(SUBSTITUTE(SUBSTITUTE(SUBSTITUTE(SUBSTITUTE(SUBSTITUTE(SUBSTITUTE(SUBSTITUTE(SUBSTITUTE(SUBSTITUTE(IF(--MID(TEXT(ABS(E17),"000000000000000"),1,3)=0,"",MID(TEXT(ABS(E17),"000000000000000"),1,1)&" ratus "&MID(TEXT(ABS(E17),"000000000000000"),2,1)&" puluh "&MID(TEXT(ABS(E17),"000000000000000"),3,1)&" trilyun ")&IF(--MID(TEXT(ABS(E17),"000000000000000"),4,3)=0,"",MID(TEXT(ABS(E17),"000000000000000"),4,1)&" ratus "&MID(TEXT(ABS(E17),"000000000000000"),5,1)&" puluh "&MID(TEXT(ABS(E17),"000000000000000"),6,1)&" milyar ")&IF(--MID(TEXT(ABS(E17),"000000000000000"),7,3)=0,"",MID(TEXT(ABS(E17),"000000000000000"),7,1)&" ratus "&MID(TEXT(ABS(E17),"000000000000000"),8,1)&" puluh "&MID(TEXT(ABS(E17),"000000000000000"),9,1)&" juta ")&IF(--MID(TEXT(ABS(E17),"000000000000000"),10,3)=0,"",IF(--MID(TEXT(ABS(E17),"000000000000000"),10,3)=1,"*",MID(TEXT(ABS(E17),"000000000000000"),10,1)&" ratus "&MID(TEXT(ABS(E17),"000000000000000"),11,1)&" puluh ")&MID(TEXT(ABS(E17),"000000000000000"),12,1)&" ribu ")&IF(--MID(TEXT(ABS(E17),"000000000000000"),13,3)=0,"",MID(TEXT(ABS(E17),"000000000000000"),13,1)&" ratus "&MID(TEXT(ABS(E17),"000000000000000"),14,1)&" puluh "&MID(TEXT(ABS(E17),"000000000000000"),15,1)),1,"satu"),2,"dua"),3,"tiga"),4,"empat"),5,"lima"),6,"enam"),7,"tujuh"),8,"delapan"),9,"sembilan"),"0 ratus",""),"0 puluh",""),"satu puluh 0","sepuluh"),"satu puluh satu","sebelas"),"satu puluh dua","duabelas"),"satu puluh tiga","tigabelas"),"satu puluh empat","empatbelas"),"satu puluh lima","limabelas"),"satu puluh enam","enambelas"),"satu puluh tujuh","tujuhbelas"),"satu puluh delapan","delapanbelas"),"satu puluh sembilan","sembilanbelas"),"satu ratus","seratus"),"*satu ribu","seribu"),0,""))," "," "))&" Rupiah") -> Delapan Puluh Delapan Juta Lima Ratus Ribu Rupiah
A21: Pembebanan Pada Kode Rekening
A22: NO | B22: Kode | C22: Uraian | G22: Anggaran | H22: Akumulasi Pencairan dana Bulan Januari s/d Desember | I22: Pencairan Saat ini | J22: Sisa Anggaran
A23: 1 | C23: Program Operasional Pengelolaan Pasar | G23: --------------- | H23: --------------- | I23: --------------- | J23: ---------------
B24: 1.1 | C24: Pengembangan pasar percontohan (SNI) - 1 Pasar | G24: --------------- | H24: --------------- | I24: --------------- | J24: ---------------
C25: a. Penataan Ruang/Zonasi dan Aksebilitas | G25: 300000000 | H25: 0 | I25: 0 | J25: =G25-H25-I25 -> 300000000
C26: b. Pembangunan Fasilitas Umum : Kantor, Toilet, Ruang Laktasi, Pos Keamanan, Tempat Ibadah, dll | G26: 450000000 | H26: 0 | I26: 0 | J26: =G26-H26-I26 -> 450000000
C27: c. Pembangunan Infrastruktur : Instalasi Air Bersih, Limbah, Listrik, Pengelolaan Sampah, Drainase, Sirkulasi Udara, dll | G27: 250000000 | H27: 0 | I27: 0 | J27: =G27-H27-I27 -> 250000000
B28: 1.2 | C28: Tata Letak Display Produk Dalam Pasar (Untuk Pasar-Pasar Berlantai Dua) | G28: 100000000 | H28: 0 | I28: 0 | J28: =G28-H28-I28 -> 100000000
B29: 1.3 | C29: Perbaikan dan Pengadaan Sarana Pengelolaan Pasar | G29: --------------- | H29: --------------- | I29: --------------- | J29: ---------------
C30: a. Pengadaan Mobil/Truck Box/Pickup/Freezer ox | G30: 550000000 | H30: 0 | I30: 0 | J30: =G30-H30-I30 -> 550000000
C31: b. Alat Pemadam Kebakaran Pasar/APAR/Mesin Pemadam | G31: 150000000 | H31: 0 | I31: 0 | J31: =G31-H31-I31 -> 150000000
C32: c. Pengadaan Bak/Kontainer Truck | G32: 200000000 | H32: 0 | I32: 88500000 | J32: =G32-H32-I32 -> 111500000
C33: d. Pengadaan CCTV Pasar | G33: 100000000 | H33: 0 | I33: 0 | J33: =G33-H33-I33 -> 100000000
C34: e. Pengadaan Papan Nama Pasar | G34: 150000000 | H34: 0 | I34: 0 | J34: =G34-H34-I34 -> 150000000
C35: f. Pengadaan Instalasi Listrik Pasar | G35: 350000000 | H35: 0 | I35: 0 | J35: =G35-H35-I35 -> 350000000
B36: 1.4 | C36: Pengembangan Wisata Pasar Yang Memiliki Keunikan Atau Pasar Tematik Yang Menawarkan Produk-produk Khusus | G36: --------------- | H36: --------------- | I36: --------------- | J36: ---------------
C37: a. Pasar Tungging - Penambahan Kios Kuliner Malam 20 Buah, Pemasangan Paving Blok dan Penambahan Lampu Halaman | G37: 200000000 | H37: 0 | I37: 0 | J37: =G37-H37-I37 -> 200000000
C38: b. Pasar Cemara - Pusat Oleh-oleh dan Pasar Kuliner Khas Banjarmasin | G38: 160000000 | H38: 0 | I38: 0 | J38: =G38-H38-I38 -> 160000000
B39: 1.5 | C39: Revitalisasi atau Pembangunan Pasar | G39: --------------- | H39: --------------- | I39: --------------- | J39: ---------------
C40: a. Pasar Baru Permai Dasar - Pemasangan ACP dan Cutting ACP, Pemasangan Neon Box Perusahaan | G40: 500000000 | H40: 0 | I40: 0 | J40: =G40-H40-I40 -> 500000000
C41: b. Pasar Antasari - Perbaikan Toko/Kios/Lapak/Ruang | G41: 500000000 | H41: 0 | I41: 0 | J41: =G41-H41-I41 -> 500000000
C42: c. Pasar Teluk Dalam - Sport Hall, Aula Serbaguna, Game Center, dan atau Playground, Paving, Perbaikan Jembatan | G42: 750000000 | H42: 0 | I42: 0 | J42: =G42-H42-I42 -> 750000000
C43: d. Pasar Kuripan - Masuk Dalam Proyek Pelebaran Jalan (Masih Kordinasi Lintas SKPD) | G43: 390000000 | H43: 0 | I43: 0 | J43: =G43-H43-I43 -> 390000000
C44: e. Pasar Malabar - Ruang Kreasi Olahraga | G44: 360000000 | H44: 0 | I44: 0 | J44: =G44-H44-I44 -> 360000000
B45: 1.6 | C45: Perbaikan Akses Menuju Jalan Pasar Dengan Melakukan Penataan Jalan, Pedestrian, Lampu Jalan dan Akses Angkutan Umum | G45: --------------- | H45: --------------- | I45: --------------- | J45: ---------------
C46: a. Perbaikan Akses Jalan : Pasar Lima/Pasar Cemara/Pasar Jahri Saleh | G46: 50000000 | H46: 0 | I46: 0 | J46: =G46-H46-I46 -> 50000000
C47: b. Penambahan Penerangan : Pasar Pandu/Pasar Pekauman/Pasar Gadang/Pasar Telawang | G47: 50000000 | H47: 0 | I47: 0 | J47: =G47-H47-I47 -> 50000000
C48: JUMLAH | G48: =SUM(G23:G47) -> 5560000000 | H48: =SUM(H24:H35) -> 0 | I48: =SUM(I24:I36) -> 88500000 | J48: =SUM(J24:J47) -> 5471500000
A50: Jumlah Yang Diminta | D50: : | E50: =I48 -> 88500000
A51: PPN | D51: :
...

Sheet FEBRUARI
A8: NOTA PENCAIRAN DANA (NPD)
A9: Nomor : 101/DIV-KEU/PPB/II/2026
A10: BENDAHARA PENGELUARAN
A11: PERUMDA PASAR BANJARMASIN
A12: Supaya mencairkan dana kepada
A14: 1. Sub Kegiatan | D14: : | E14: Beban Investasi
A15: 2. Nomor | D15: : | E15: 2.1.2
A16: 3. Tahun Anggaran | D16: : | E16: 2026
A17: 4. Jumlah Yang Diminta | D17: : | E17: =I48 -> 2760000
E18: =PROPER(IF(E17=0,"nol",IF(E17<0,"minus ","")&SUBSTITUTE(TRIM(SUBSTITUTE(SUBSTITUTE(SUBSTITUTE(SUBSTITUTE(SUBSTITUTE(SUBSTITUTE(SUBSTITUTE(SUBSTITUTE(SUBSTITUTE(SUBSTITUTE(SUBSTITUTE(SUBSTITUTE(SUBSTITUTE(SUBSTITUTE(SUBSTITUTE(SUBSTITUTE(SUBSTITUTE(SUBSTITUTE(SUBSTITUTE(SUBSTITUTE(SUBSTITUTE(SUBSTITUTE(SUBSTITUTE(SUBSTITUTE(IF(--MID(TEXT(ABS(E17),"000000000000000"),1,3)=0,"",MID(TEXT(ABS(E17),"000000000000000"),1,1)&" ratus "&MID(TEXT(ABS(E17),"000000000000000"),2,1)&" puluh "&MID(TEXT(ABS(E17),"000000000000000"),3,1)&" trilyun ")&IF(--MID(TEXT(ABS(E17),"000000000000000"),4,3)=0,"",MID(TEXT(ABS(E17),"000000000000000"),4,1)&" ratus "&MID(TEXT(ABS(E17),"000000000000000"),5,1)&" puluh "&MID(TEXT(ABS(E17),"000000000000000"),6,1)&" milyar ")&IF(--MID(TEXT(ABS(E17),"000000000000000"),7,3)=0,"",MID(TEXT(ABS(E17),"000000000000000"),7,1)&" ratus "&MID(TEXT(ABS(E17),"000000000000000"),8,1)&" puluh "&MID(TEXT(ABS(E17),"000000000000000"),9,1)&" juta ")&IF(--MID(TEXT(ABS(E17),"000000000000000"),10,3)=0,"",IF(--MID(TEXT(ABS(E17),"000000000000000"),10,3)=1,"*",MID(TEXT(ABS(E17),"000000000000000"),10,1)&" ratus "&MID(TEXT(ABS(E17),"000000000000000"),11,1)&" puluh ")&MID(TEXT(ABS(E17),"000000000000000"),12,1)&" ribu ")&IF(--MID(TEXT(ABS(E17),"000000000000000"),13,3)=0,"",MID(TEXT(ABS(E17),"000000000000000"),13,1)&" ratus "&MID(TEXT(ABS(E17),"000000000000000"),14,1)&" puluh "&MID(TEXT(ABS(E17),"000000000000000"),15,1)),1,"satu"),2,"dua"),3,"tiga"),4,"empat"),5,"lima"),6,"enam"),7,"tujuh"),8,"delapan"),9,"sembilan"),"0 ratus",""),"0 puluh",""),"satu puluh 0","sepuluh"),"satu puluh satu","sebelas"),"satu puluh dua","duabelas"),"satu puluh tiga","tigabelas"),"satu puluh empat","empatbelas"),"satu puluh lima","limabelas"),"satu puluh enam","enambelas"),"satu puluh tujuh","tujuhbelas"),"satu puluh delapan","delapanbelas"),"satu puluh sembilan","sembilanbelas"),"satu ratus","seratus"),"*satu ribu","seribu"),0,""))," "," "))&" Rupiah") -> Dua Juta Tujuh Ratus Enam Puluh Ribu Rupiah
A21: Pembebanan Pada Kode Rekening
A22: NO | B22: Kode | C22: Uraian | G22: Anggaran | H22: Akumulasi Pencairan dana Bulan Januari s/d Desember | I22: Pencairan Saat ini | J22: Sisa Anggaran
A23: 1 | C23: Program Operasional Pengelolaan Pasar | G23: --------------- | H23: --------------- | I23: --------------- | J23: ---------------
B24: 1.1 | C24: Pengembangan pasar percontohan (SNI) - 1 Pasar | G24: --------------- | H24: --------------- | I24: --------------- | J24: ---------------
C25: a. Penataan Ruang/Zonasi dan Aksebilitas | G25: 300000000 | H25: =JANUARI!H25+JANUARI!I25 -> 0 | I25: 0 | J25: =G25-H25-I25 -> 300000000
C26: b. Pembangunan Fasilitas Umum : Kantor, Toilet, Ruang Laktasi, Pos Keamanan, Tempat Ibadah, dll | G26: 450000000 | H26: =JANUARI!H26+JANUARI!I26 -> 0 | I26: 0 | J26: =G26-H26-I26 -> 450000000
C27: c. Pembangunan Infrastruktur : Instalasi Air Bersih, Limbah, Listrik, Pengelolaan Sampah, Drainase, Sirkulasi Udara, dll | G27: 250000000 | H27: =JANUARI!H27+JANUARI!I27 -> 0 | I27: 0 | J27: =G27-H27-I27 -> 250000000
B28: 1.2 | C28: Tata Letak Display Produk Dalam Pasar (Untuk Pasar-Pasar Berlantai Dua) | G28: 100000000 | H28: =JANUARI!H28+JANUARI!I28 -> 0 | I28: 0 | J28: =G28-H28-I28 -> 100000000
B29: 1.3 | C29: Perbaikan dan Pengadaan Sarana Pengelolaan Pasar | G29: --------------- | H29: --------------- | I29: --------------- | J29: ---------------
C30: a. Pengadaan Mobil/Truck Box/Pickup/Freezer ox | G30: 550000000 | H30: =JANUARI!H30+JANUARI!I30 -> 0 | I30: 0 | J30: =G30-H30-I30 -> 550000000
C31: b. Alat Pemadam Kebakaran Pasar/APAR/Mesin Pemadam | G31: 150000000 | H31: =JANUARI!H31+JANUARI!I31 -> 0 | I31: 0 | J31: =G31-H31-I31 -> 150000000
C32: c. Pengadaan Bak/Kontainer Truck | G32: 200000000 | H32: =JANUARI!H32+JANUARI!I32 -> 88500000 | I32: 0 | J32: =G32-H32-I32 -> 111500000
C33: d. Pengadaan CCTV Pasar | G33: 100000000 | H33: =JANUARI!H33+JANUARI!I33 -> 0 | I33: 0 | J33: =G33-H33-I33 -> 100000000
C34: e. Pengadaan Papan Nama Pasar | G34: 150000000 | H34: =JANUARI!H34+JANUARI!I34 -> 0 | I34: 0 | J34: =G34-H34-I34 -> 150000000
C35: f. Pengadaan Instalasi Listrik Pasar | G35: 350000000 | H35: =JANUARI!H35+JANUARI!I35 -> 0 | I35: 2760000 | J35: =G35-H35-I35 -> 347240000
B36: 1.4 | C36: Pengembangan Wisata Pasar Yang Memiliki Keunikan Atau Pasar Tematik Yang Menawarkan Produk-produk Khusus | G36: --------------- | H36: --------------- | I36: --------------- | J36: ---------------
C37: a. Pasar Tungging - Penambahan Kios Kuliner Malam 20 Buah, Pemasangan Paving Blok dan Penambahan Lampu Halaman | G37: 200000000 | H37: =JANUARI!H37+JANUARI!I37 -> 0 | I37: 0 | J37: =G37-H37-I37 -> 200000000
C38: b. Pasar Cemara - Pusat Oleh-oleh dan Pasar Kuliner Khas Banjarmasin | G38: 160000000 | H38: =JANUARI!H38+JANUARI!I38 -> 0 | I38: 0 | J38: =G38-H38-I38 -> 160000000
B39: 1.5 | C39: Revitalisasi atau Pembangunan Pasar | G39: --------------- | H39: --------------- | I39: --------------- | J39: ---------------
C40: a. Pasar Baru Permai Dasar - Pemasangan ACP dan Cutting ACP, Pemasangan Neon Box Perusahaan | G40: 500000000 | H40: =JANUARI!H40+JANUARI!I40 -> 0 | I40: 0 | J40: =G40-H40-I40 -> 500000000
C41: b. Pasar Antasari - Perbaikan Toko/Kios/Lapak/Ruang | G41: 500000000 | H41: =JANUARI!H41+JANUARI!I41 -> 0 | I41: 0 | J41: =G41-H41-I41 -> 500000000
C42: c. Pasar Teluk Dalam - Sport Hall, Aula Serbaguna, Game Center, dan atau Playground, Paving, Perbaikan Jembatan | G42: 750000000 | H42: =JANUARI!H42+JANUARI!I42 -> 0 | I42: 0 | J42: =G42-H42-I42 -> 750000000
C43: d. Pasar Kuripan - Masuk Dalam Proyek Pelebaran Jalan (Masih Kordinasi Lintas SKPD) | G43: 390000000 | H43: =JANUARI!H43+JANUARI!I43 -> 0 | I43: 0 | J43: =G43-H43-I43 -> 390000000
C44: e. Pasar Malabar - Ruang Kreasi Olahraga | G44: 360000000 | H44: =JANUARI!H44+JANUARI!I44 -> 0 | I44: 0 | J44: =G44-H44-I44 -> 360000000
B45: 1.6 | C45: Perbaikan Akses Menuju Jalan Pasar Dengan Melakukan Penataan Jalan, Pedestrian, Lampu Jalan dan Akses Angkutan Umum | G45: --------------- | H45: --------------- | I45: --------------- | J45: ---------------
C46: a. Perbaikan Akses Jalan : Pasar Lima/Pasar Cemara/Pasar Jahri Saleh | G46: 50000000 | H46: =JANUARI!H46+JANUARI!I46 -> 0 | I46: 0 | J46: =G46-H46-I46 -> 50000000
C47: b. Penambahan Penerangan : Pasar Pandu/Pasar Pekauman/Pasar Gadang/Pasar Telawang | G47: 50000000 | H47: =JANUARI!H47+JANUARI!I47 -> 0 | I47: 0 | J47: =G47-H47-I47 -> 50000000
C48: JUMLAH | G48: =SUM(G23:G47) -> 5560000000 | H48: =SUM(H24:H35) -> 88500000 | I48: =SUM(I24:I36) -> 2760000 | J48: =SUM(J24:J47) -> 5468740000
A50: Jumlah Yang Diminta | D50: : | E50: =I48 -> 2760000
A51: PPN | D51: :
...

Sheet MARET
A8: NOTA PENCAIRAN DANA (NPD)
A9: Nomor : 013/DIV-KEU/PPB/III/2026
A10: BENDAHARA PENGELUARAN
A11: PERUMDA PASAR BANJARMASIN
A12: Supaya mencairkan dana kepada
A14: 1. Sub Kegiatan | D14: : | E14: Beban Investasi
A15: 2. Nomor | D15: : | E15: 2.1.2
A16: 3. Tahun Anggaran | D16: : | E16: 2026
A17: 4. Jumlah Yang Diminta | D17: : | E17: =I48 -> 88500000
E18: =PROPER(IF(E17=0,"nol",IF(E17<0,"minus ","")&SUBSTITUTE(TRIM(SUBSTITUTE(SUBSTITUTE(SUBSTITUTE(SUBSTITUTE(SUBSTITUTE(SUBSTITUTE(SUBSTITUTE(SUBSTITUTE(SUBSTITUTE(SUBSTITUTE(SUBSTITUTE(SUBSTITUTE(SUBSTITUTE(SUBSTITUTE(SUBSTITUTE(SUBSTITUTE(SUBSTITUTE(SUBSTITUTE(SUBSTITUTE(SUBSTITUTE(SUBSTITUTE(SUBSTITUTE(SUBSTITUTE(SUBSTITUTE(IF(--MID(TEXT(ABS(E17),"000000000000000"),1,3)=0,"",MID(TEXT(ABS(E17),"000000000000000"),1,1)&" ratus "&MID(TEXT(ABS(E17),"000000000000000"),2,1)&" puluh "&MID(TEXT(ABS(E17),"000000000000000"),3,1)&" trilyun ")&IF(--MID(TEXT(ABS(E17),"000000000000000"),4,3)=0,"",MID(TEXT(ABS(E17),"000000000000000"),4,1)&" ratus "&MID(TEXT(ABS(E17),"000000000000000"),5,1)&" puluh "&MID(TEXT(ABS(E17),"000000000000000"),6,1)&" milyar ")&IF(--MID(TEXT(ABS(E17),"000000000000000"),7,3)=0,"",MID(TEXT(ABS(E17),"000000000000000"),7,1)&" ratus "&MID(TEXT(ABS(E17),"000000000000000"),8,1)&" puluh "&MID(TEXT(ABS(E17),"000000000000000"),9,1)&" juta ")&IF(--MID(TEXT(ABS(E17),"000000000000000"),10,3)=0,"",IF(--MID(TEXT(ABS(E17),"000000000000000"),10,3)=1,"*",MID(TEXT(ABS(E17),"000000000000000"),10,1)&" ratus "&MID(TEXT(ABS(E17),"000000000000000"),11,1)&" puluh ")&MID(TEXT(ABS(E17),"000000000000000"),12,1)&" ribu ")&IF(--MID(TEXT(ABS(E17),"000000000000000"),13,3)=0,"",MID(TEXT(ABS(E17),"000000000000000"),13,1)&" ratus "&MID(TEXT(ABS(E17),"000000000000000"),14,1)&" puluh "&MID(TEXT(ABS(E17),"000000000000000"),15,1)),1,"satu"),2,"dua"),3,"tiga"),4,"empat"),5,"lima"),6,"enam"),7,"tujuh"),8,"delapan"),9,"sembilan"),"0 ratus",""),"0 puluh",""),"satu puluh 0","sepuluh"),"satu puluh satu","sebelas"),"satu puluh dua","duabelas"),"satu puluh tiga","tigabelas"),"satu puluh empat","empatbelas"),"satu puluh lima","limabelas"),"satu puluh enam","enambelas"),"satu puluh tujuh","tujuhbelas"),"satu puluh delapan","delapanbelas"),"satu puluh sembilan","sembilanbelas"),"satu ratus","seratus"),"*satu ribu","seribu"),0,""))," "," "))&" Rupiah") -> Delapan Puluh Delapan Juta Lima Ratus Ribu Rupiah
A21: Pembebanan Pada Kode Rekening
A22: NO | B22: Kode | C22: Uraian | G22: Anggaran | H22: Akumulasi Pencairan dana Bulan Januari s/d Desember | I22: Pencairan Saat ini | J22: Sisa Anggaran
A23: 1 | C23: Program Operasional Pengelolaan Pasar | G23: --------------- | H23: --------------- | I23: --------------- | J23: ---------------
B24: 1.1 | C24: Pengembangan pasar percontohan (SNI) - 1 Pasar | G24: --------------- | H24: --------------- | I24: --------------- | J24: ---------------
C25: a. Penataan Ruang/Zonasi dan Aksebilitas | G25: 300000000 | H25: =FEBRUARI!H157+FEBRUARI!I157 -> 0 | I25: 0 | J25: =G25-H25-I25 -> 300000000
C26: b. Pembangunan Fasilitas Umum : Kantor, Toilet, Ruang Laktasi, Pos Keamanan, Tempat Ibadah, dll | G26: 450000000 | H26: =FEBRUARI!H158+FEBRUARI!I158 -> 0 | I26: 0 | J26: =G26-H26-I26 -> 450000000
C27: c. Pembangunan Infrastruktur : Instalasi Air Bersih, Limbah, Listrik, Pengelolaan Sampah, Drainase, Sirkulasi Udara, dll | G27: 250000000 | H27: =FEBRUARI!H159+FEBRUARI!I159 -> 0 | I27: 0 | J27: =G27-H27-I27 -> 250000000
B28: 1.2 | C28: Tata Letak Display Produk Dalam Pasar (Untuk Pasar-Pasar Berlantai Dua) | G28: 100000000 | H28: =FEBRUARI!H160+FEBRUARI!I160 -> 0 | I28: 0 | J28: =G28-H28-I28 -> 100000000
B29: 1.3 | C29: Perbaikan dan Pengadaan Sarana Pengelolaan Pasar | G29: --------------- | H29: --------------- | I29: --------------- | J29: ---------------
C30: a. Pengadaan Mobil/Truck Box/Pickup/Freezer ox | G30: 550000000 | H30: =FEBRUARI!H162+FEBRUARI!I162 -> 0 | I30: 0 | J30: =G30-H30-I30 -> 550000000
C31: b. Alat Pemadam Kebakaran Pasar/APAR/Mesin Pemadam | G31: 150000000 | H31: =FEBRUARI!H163+FEBRUARI!I163 -> 9852350 | I31: 0 | J31: =G31-H31-I31 -> 140147650
C32: c. Pengadaan Bak/Kontainer Truck | G32: 200000000 | H32: =FEBRUARI!H164+FEBRUARI!I164 -> 88500000 | I32: 88500000 | J32: =G32-H32-I32 -> 23000000
C33: d. Pengadaan CCTV Pasar | G33: 100000000 | H33: =FEBRUARI!H165+FEBRUARI!I165 -> 19958500 | I33: 0 | J33: =G33-H33-I33 -> 80041500
C34: e. Pengadaan Papan Nama Pasar | G34: 150000000 | H34: =FEBRUARI!H166+FEBRUARI!I166 -> 0 | I34: 0 | J34: =G34-H34-I34 -> 150000000
C35: f. Pengadaan Instalasi Listrik Pasar | G35: 350000000 | H35: =FEBRUARI!H167+FEBRUARI!I167 -> 2760000 | I35: 0 | J35: =G35-H35-I35 -> 347240000
B36: 1.4 | C36: Pengembangan Wisata Pasar Yang Memiliki Keunikan Atau Pasar Tematik Yang Menawarkan Produk-produk Khusus | G36: --------------- | H36: --------------- | I36: --------------- | J36: ---------------
C37: a. Pasar Tungging - Penambahan Kios Kuliner Malam 20 Buah, Pemasangan Paving Blok dan Penambahan Lampu Halaman | G37: 200000000 | H37: =FEBRUARI!H169+FEBRUARI!I169 -> 0 | I37: 0 | J37: =G37-H37-I37 -> 200000000
C38: b. Pasar Cemara - Pusat Oleh-oleh dan Pasar Kuliner Khas Banjarmasin | G38: 160000000 | H38: =FEBRUARI!H170+FEBRUARI!I170 -> 0 | I38: 0 | J38: =G38-H38-I38 -> 160000000
B39: 1.5 | C39: Revitalisasi atau Pembangunan Pasar | G39: --------------- | H39: --------------- | I39: --------------- | J39: ---------------
C40: a. Pasar Baru Permai Dasar - Pemasangan ACP dan Cutting ACP, Pemasangan Neon Box Perusahaan | G40: 500000000 | H40: =FEBRUARI!H172+FEBRUARI!I172 -> 0 | I40: 0 | J40: =G40-H40-I40 -> 500000000
C41: b. Pasar Antasari - Perbaikan Toko/Kios/Lapak/Ruang | G41: 500000000 | H41: =FEBRUARI!H173+FEBRUARI!I173 -> 0 | I41: 0 | J41: =G41-H41-I41 -> 500000000
C42: c. Pasar Teluk Dalam - Sport Hall, Aula Serbaguna, Game Center, dan atau Playground, Paving, Perbaikan Jembatan | G42: 750000000 | H42: =FEBRUARI!H174+FEBRUARI!I174 -> 0 | I42: 0 | J42: =G42-H42-I42 -> 750000000
C43: d. Pasar Kuripan - Masuk Dalam Proyek Pelebaran Jalan (Masih Kordinasi Lintas SKPD) | G43: 390000000 | H43: =FEBRUARI!H175+FEBRUARI!I175 -> 0 | I43: 0 | J43: =G43-H43-I43 -> 390000000
C44: e. Pasar Malabar - Ruang Kreasi Olahraga | G44: 360000000 | H44: =FEBRUARI!H176+FEBRUARI!I176 -> 0 | I44: 0 | J44: =G44-H44-I44 -> 360000000
B45: 1.6 | C45: Perbaikan Akses Menuju Jalan Pasar Dengan Melakukan Penataan Jalan, Pedestrian, Lampu Jalan dan Akses Angkutan Umum | G45: --------------- | H45: --------------- | I45: --------------- | J45: ---------------
C46: a. Perbaikan Akses Jalan : Pasar Lima/Pasar Cemara/Pasar Jahri Saleh | G46: 50000000 | H46: =FEBRUARI!H178+FEBRUARI!I178 -> 0 | I46: 0 | J46: =G46-H46-I46 -> 50000000
C47: b. Penambahan Penerangan : Pasar Pandu/Pasar Pekauman/Pasar Gadang/Pasar Telawang | G47: 50000000 | H47: =FEBRUARI!H179+FEBRUARI!I179 -> 0 | I47: 0 | J47: =G47-H47-I47 -> 50000000
C48: JUMLAH | G48: =SUM(G23:G47) -> 5560000000 | H48: =SUM(H24:H35) -> 121070850 | I48: =SUM(I24:I36) -> 88500000 | J48: =SUM(J24:J47) -> 5350429150
A50: Jumlah Yang Diminta | D50: : | E50: =I48 -> 88500000
A51: PPN | D51: :
...
