Workbook

Sheet JANUARI
A8: NOTA PENCIRAN DANA (NPD)
A9: Nomor : 23/DIV-KEU/PPB/I/2026
A10: BENDAHARA PENGELUARAN
A11: PERUMDA PASAR BANJARMASIN
A12: Supaya Mencairkan Dana
A14: 1. Sub Kegiatan | D14: : | E14: Beban Umum & Keuangan
A15: 2. Nomor | D15: : | E15: 2.1.4
A16: 3. Tahun Anggaran | D16: : | E16: 2026
A17: 4. Jumlah Yang Diminta | D17: : | E17: =J29 -> 6370185
D18: : | E18: =PROPER(IF(E17=0,"nol",IF(E17<0,"minus ","")&SUBSTITUTE(TRIM(SUBSTITUTE(SUBSTITUTE(SUBSTITUTE(SUBSTITUTE(SUBSTITUTE(SUBSTITUTE(SUBSTITUTE(SUBSTITUTE(SUBSTITUTE(SUBSTITUTE(SUBSTITUTE(SUBSTITUTE(SUBSTITUTE(SUBSTITUTE(SUBSTITUTE(SUBSTITUTE(SUBSTITUTE(SUBSTITUTE(SUBSTITUTE(SUBSTITUTE(SUBSTITUTE(SUBSTITUTE(SUBSTITUTE(SUBSTITUTE(IF(--MID(TEXT(ABS(E17),"000000000000000"),1,3)=0,"",MID(TEXT(ABS(E17),"000000000000000"),1,1)&" ratus "&MID(TEXT(ABS(E17),"000000000000000"),2,1)&" puluh "&MID(TEXT(ABS(E17),"000000000000000"),3,1)&" trilyun ")&IF(--MID(TEXT(ABS(E17),"000000000000000"),4,3)=0,"",MID(TEXT(ABS(E17),"000000000000000"),4,1)&" ratus "&MID(TEXT(ABS(E17),"000000000000000"),5,1)&" puluh "&MID(TEXT(ABS(E17),"000000000000000"),6,1)&" milyar ")&IF(--MID(TEXT(ABS(E17),"000000000000000"),7,3)=0,"",MID(TEXT(ABS(E17),"000000000000000"),7,1)&" ratus "&MID(TEXT(ABS(E17),"000000000000000"),8,1)&" puluh "&MID(TEXT(ABS(E17),"000000000000000"),9,1)&" juta ")&IF(--MID(TEXT(ABS(E17),"000000000000000"),10,3)=0,"",IF(--MID(TEXT(ABS(E17),"000000000000000"),10,3)=1,"*",MID(TEXT(ABS(E17),"000000000000000"),10,1)&" ratus "&MID(TEXT(ABS(E17),"000000000000000"),11,1)&" puluh ")&MID(TEXT(ABS(E17),"000000000000000"),12,1)&" ribu ")&IF(--MID(TEXT(ABS(E17),"000000000000000"),13,3)=0,"",MID(TEXT(ABS(E17),"000000000000000"),13,1)&" ratus "&MID(TEXT(ABS(E17),"000000000000000"),14,1)&" puluh "&MID(TEXT(ABS(E17),"000000000000000"),15,1)),1,"satu"),2,"dua"),3,"tiga"),4,"empat"),5,"lima"),6,"enam"),7,"tujuh"),8,"delapan"),9,"sembilan"),"0 ratus",""),"0 puluh",""),"satu puluh 0","sepuluh"),"satu puluh satu","sebelas"),"satu puluh dua","duabelas"),"satu puluh tiga","tigabelas"),"satu puluh empat","empatbelas"),"satu puluh lima","limabelas"),"satu puluh enam","enambelas"),"satu puluh tujuh","tujuhbelas"),"satu puluh delapan","delapanbelas"),"satu puluh sembilan","sembilanbelas"),"satu ratus","seratus"),"*satu ribu","seribu"),0,""))," "," "))&" Rupiah") -> Enam Juta Tiga Ratus Tujuh Puluh Ribu Seratus Delapan Puluh Lima Rupiah
A21: Pembebanan Pada Kode Rekening
A22: NO | B22: Kode | C22: Uraian | G22: Anggaran | H22: Akumulasi Pencairan dana Bulan Januari s/d Desember | J22: Pencairan Saat ini | K22: Sisa Anggaran
A23: 1 | C23: Beban Telepon/Listrik/Air/Wifi/Website | G23: --------------- | H23: --------------- | J23: --------------- | K23: ---------------
B24: 1.1 | C24: Biaya Telepon/Pulsa/Paket Data Hp Operasional | G24: 12000000 | H24: 0 | J24: 0 | K24: =G24-H24-J24 -> 12000000
B25: 1.2 | C25: Biaya Air | G25: 18000000 | H25: 0 | J25: 1192745 | K25: =G25-H25-J25 -> 16807255
B26: 1.3 | C26: Biaya Listrik | G26: 80000000 | H26: 0 | J26: 4273340 | K26: =G26-H26-J26 -> 75726660
B27: 1.4 | C27: Biaya Wifi/Internet | G27: 20400000 | H27: 0 | J27: 904100 | K27: =G27-H27-J27 -> 19495900
B28: 1.5 | C28: Biaya Website dan Aplikasi | G28: 50000000 | H28: 0 | J28: 0 | K28: =G28-H28-J28 -> 50000000
C29: JUMLAH | G29: =SUM(G23:G28) -> 180400000 | H29: =SUM(H23:H28) -> 0 | J29: =SUM(J23:J28) -> 6370185 | K29: =SUM(K23:K28) -> 174029815
A31: Jumlah Yang Diminta | D31: : | E31: =J29 -> 6370185
A32: PPN | D32: :
A33: PPh Psl 21/22/23/4(2) | D33: :
A34: Jumlah Potongan | D34: : | E34: =E32+E33 -> 0
A36: Jumlah yang dibayarkan | D36: : | E36: =E31-E34 -> 6370185
E37: =PROPER(IF(E36=0,"nol",IF(E36<0,"minus ","")&SUBSTITUTE(TRIM(SUBSTITUTE(SUBSTITUTE(SUBSTITUTE(SUBSTITUTE(SUBSTITUTE(SUBSTITUTE(SUBSTITUTE(SUBSTITUTE(SUBSTITUTE(SUBSTITUTE(SUBSTITUTE(SUBSTITUTE(SUBSTITUTE(SUBSTITUTE(SUBSTITUTE(SUBSTITUTE(SUBSTITUTE(SUBSTITUTE(SUBSTITUTE(SUBSTITUTE(SUBSTITUTE(SUBSTITUTE(SUBSTITUTE(SUBSTITUTE(IF(--MID(TEXT(ABS(E36),"000000000000000"),1,3)=0,"",MID(TEXT(ABS(E36),"000000000000000"),1,1)&" ratus "&MID(TEXT(ABS(E36),"000000000000000"),2,1)&" puluh "&MID(TEXT(ABS(E36),"000000000000000"),3,1)&" trilyun ")&IF(--MID(TEXT(ABS(E36),"000000000000000"),4,3)=0,"",MID(TEXT(ABS(E36),"000000000000000"),4,1)&" ratus "&MID(TEXT(ABS(E36),"000000000000000"),5,1)&" puluh "&MID(TEXT(ABS(E36),"000000000000000"),6,1)&" milyar ")&IF(--MID(TEXT(ABS(E36),"000000000000000"),7,3)=0,"",MID(TEXT(ABS(E36),"000000000000000"),7,1)&" ratus "&MID(TEXT(ABS(E36),"000000000000000"),8,1)&" puluh "&MID(TEXT(ABS(E36),"000000000000000"),9,1)&" juta ")&IF(--MID(TEXT(ABS(E36),"000000000000000"),10,3)=0,"",IF(--MID(TEXT(ABS(E36),"000000000000000"),10,3)=1,"*",MID(TEXT(ABS(E36),"000000000000000"),10,1)&" ratus "&MID(TEXT(ABS(E36),"000000000000000"),11,1)&" puluh ")&MID(TEXT(ABS(E36),"000000000000000"),12,1)&" ribu ")&IF(--MID(TEXT(ABS(E36),"000000000000000"),13,3)=0,"",MID(TEXT(ABS(E36),"000000000000000"),13,1)&" ratus "&MID(TEXT(ABS(E36),"000000000000000"),14,1)&" puluh "&MID(TEXT(ABS(E36),"000000000000000"),15,1)),1,"satu"),2,"dua"),3,"tiga"),4,"empat"),5,"lima"),6,"enam"),7,"tujuh"),8,"delapan"),9,"sembilan"),"0 ratus",""),"0 puluh",""),"satu puluh 0","sepuluh"),"satu puluh satu","sebelas"),"satu puluh dua","duabelas"),"satu puluh tiga","tigabelas"),"satu puluh empat","empatbelas"),"satu puluh lima","limabelas"),"satu puluh enam","enambelas"),"satu puluh tujuh","tujuhbelas"),"satu puluh delapan","delapanbelas"),"satu puluh sembilan","sembilanbelas"),"satu ratus","seratus"),"*satu ribu","seribu"),0,""))," "," "))&" Rupiah") -> Enam Juta Tiga Ratus Tujuh Puluh Ribu Seratus Delapan Puluh Lima Rupiah
J40: Banjarmasin, 12 Januari 2026
A41: MENGETAHUI | J41: YANG MEMBUAT
A46: IRNA WAHYUNI N. | J46: M. ZULKIFLI
A55: NOTA PENCIRAN DANA (NPD)
A56: Nomor : 02/DIV-KEU/PPB/I/2026
A57: BENDAHARA PENGELUARAN
A58: PERUMDA PASAR BANJARMASIN
A59: Supaya Mencairkan Dana
A61: 1. Sub Kegiatan | D61: : | E61: Beban Umum & Keuangan
A62: 2. Nomor | D62: : | E62: 2.1.4
A63: 3. Tahun Anggaran | D63: : | E63: 2026
A64: 4. Jumlah Yang Diminta | D64: : | E64: =J76 -> 61869180
D65: : | E65: =PROPER(IF(E64=0,"nol",IF(E64<0,"minus ","")&SUBSTITUTE(TRIM(SUBSTITUTE(SUBSTITUTE(SUBSTITUTE(SUBSTITUTE(SUBSTITUTE(SUBSTITUTE(SUBSTITUTE(SUBSTITUTE(SUBSTITUTE(SUBSTITUTE(SUBSTITUTE(SUBSTITUTE(SUBSTITUTE(SUBSTITUTE(SUBSTITUTE(SUBSTITUTE(SUBSTITUTE(SUBSTITUTE(SUBSTITUTE(SUBSTITUTE(SUBSTITUTE(SUBSTITUTE(SUBSTITUTE(SUBSTITUTE(IF(--MID(TEXT(ABS(E64),"000000000000000"),1,3)=0,"",MID(TEXT(ABS(E64),"000000000000000"),1,1)&" ratus "&MID(TEXT(ABS(E64),"000000000000000"),2,1)&" puluh "&MID(TEXT(ABS(E64),"000000000000000"),3,1)&" trilyun ")&IF(--MID(TEXT(ABS(E64),"000000000000000"),4,3)=0,"",MID(TEXT(ABS(E64),"000000000000000"),4,1)&" ratus "&MID(TEXT(ABS(E64),"000000000000000"),5,1)&" puluh "&MID(TEXT(ABS(E64),"000000000000000"),6,1)&" milyar ")&IF(--MID(TEXT(ABS(E64),"000000000000000"),7,3)=0,"",MID(TEXT(ABS(E64),"000000000000000"),7,1)&" ratus "&MID(TEXT(ABS(E64),"000000000000000"),8,1)&" puluh "&MID(TEXT(ABS(E64),"000000000000000"),9,1)&" juta ")&IF(--MID(TEXT(ABS(E64),"000000000000000"),10,3)=0,"",IF(--MID(TEXT(ABS(E64),"000000000000000"),10,3)=1,"*",MID(TEXT(ABS(E64),"000000000000000"),10,1)&" ratus "&MID(TEXT(ABS(E64),"000000000000000"),11,1)&" puluh ")&MID(TEXT(ABS(E64),"000000000000000"),12,1)&" ribu ")&IF(--MID(TEXT(ABS(E64),"000000000000000"),13,3)=0,"",MID(TEXT(ABS(E64),"000000000000000"),13,1)&" ratus "&MID(TEXT(ABS(E64),"000000000000000"),14,1)&" puluh "&MID(TEXT(ABS(E64),"000000000000000"),15,1)),1,"satu"),2,"dua"),3,"tiga"),4,"empat"),5,"lima"),6,"enam"),7,"tujuh"),8,"delapan"),9,"sembilan"),"0 ratus",""),"0 puluh",""),"satu puluh 0","sepuluh"),"satu puluh satu","sebelas"),"satu puluh dua","duabelas"),"satu puluh tiga","tigabelas"),"satu puluh empat","empatbelas"),"satu puluh lima","limabelas"),"satu puluh enam","enambelas"),"satu puluh tujuh","tujuhbelas"),"satu puluh delapan","delapanbelas"),"satu puluh sembilan","sembilanbelas"),"satu ratus","seratus"),"*satu ribu","seribu"),0,""))," "," "))&" Rupiah") -> Enam Puluh Satu Juta Delapan Ratus Enam Puluh Sembilan Ribu Seratus Delapan Puluh Rupiah
A68: Pembebanan Pada Kode Rekening
A69: NO | B69: Kode | C69: Uraian | G69: Anggaran | H69: Akumulasi Pencairan dana Bulan Januari s/d Desember | J69: Pencairan Saat ini | K69: Sisa Anggaran
...

Sheet FEBRUARI
A8: NOTA PENCIRAN DANA (NPD)
A9: Nomor : 109/DIV-KEU/PPB/II/2026
A10: BENDAHARA PENGELUARAN
A11: PERUMDA PASAR BANJARMASIN
A12: Supaya Mencairkan Dana
A14: 1. Sub Kegiatan | D14: : | E14: Beban Umum & Keuangan
A15: 2. Nomor | D15: : | E15: 2.1.4
A16: 3. Tahun Anggaran | D16: : | E16: 2026
A17: 4. Jumlah Yang Diminta | D17: : | E17: =J29 -> 500000
D18: : | E18: =PROPER(IF(E17=0,"nol",IF(E17<0,"minus ","")&SUBSTITUTE(TRIM(SUBSTITUTE(SUBSTITUTE(SUBSTITUTE(SUBSTITUTE(SUBSTITUTE(SUBSTITUTE(SUBSTITUTE(SUBSTITUTE(SUBSTITUTE(SUBSTITUTE(SUBSTITUTE(SUBSTITUTE(SUBSTITUTE(SUBSTITUTE(SUBSTITUTE(SUBSTITUTE(SUBSTITUTE(SUBSTITUTE(SUBSTITUTE(SUBSTITUTE(SUBSTITUTE(SUBSTITUTE(SUBSTITUTE(SUBSTITUTE(IF(--MID(TEXT(ABS(E17),"000000000000000"),1,3)=0,"",MID(TEXT(ABS(E17),"000000000000000"),1,1)&" ratus "&MID(TEXT(ABS(E17),"000000000000000"),2,1)&" puluh "&MID(TEXT(ABS(E17),"000000000000000"),3,1)&" trilyun ")&IF(--MID(TEXT(ABS(E17),"000000000000000"),4,3)=0,"",MID(TEXT(ABS(E17),"000000000000000"),4,1)&" ratus "&MID(TEXT(ABS(E17),"000000000000000"),5,1)&" puluh "&MID(TEXT(ABS(E17),"000000000000000"),6,1)&" milyar ")&IF(--MID(TEXT(ABS(E17),"000000000000000"),7,3)=0,"",MID(TEXT(ABS(E17),"000000000000000"),7,1)&" ratus "&MID(TEXT(ABS(E17),"000000000000000"),8,1)&" puluh "&MID(TEXT(ABS(E17),"000000000000000"),9,1)&" juta ")&IF(--MID(TEXT(ABS(E17),"000000000000000"),10,3)=0,"",IF(--MID(TEXT(ABS(E17),"000000000000000"),10,3)=1,"*",MID(TEXT(ABS(E17),"000000000000000"),10,1)&" ratus "&MID(TEXT(ABS(E17),"000000000000000"),11,1)&" puluh ")&MID(TEXT(ABS(E17),"000000000000000"),12,1)&" ribu ")&IF(--MID(TEXT(ABS(E17),"000000000000000"),13,3)=0,"",MID(TEXT(ABS(E17),"000000000000000"),13,1)&" ratus "&MID(TEXT(ABS(E17),"000000000000000"),14,1)&" puluh "&MID(TEXT(ABS(E17),"000000000000000"),15,1)),1,"satu"),2,"dua"),3,"tiga"),4,"empat"),5,"lima"),6,"enam"),7,"tujuh"),8,"delapan"),9,"sembilan"),"0 ratus",""),"0 puluh",""),"satu puluh 0","sepuluh"),"satu puluh satu","sebelas"),"satu puluh dua","duabelas"),"satu puluh tiga","tigabelas"),"satu puluh empat","empatbelas"),"satu puluh lima","limabelas"),"satu puluh enam","enambelas"),"satu puluh tujuh","tujuhbelas"),"satu puluh delapan","delapanbelas"),"satu puluh sembilan","sembilanbelas"),"satu ratus","seratus"),"*satu ribu","seribu"),0,""))," "," "))&" Rupiah") -> Lima Ratus Ribu Rupiah
A21: Pembebanan Pada Kode Rekening
A22: NO | B22: Kode | C22: Uraian | G22: Anggaran | H22: Akumulasi Pencairan dana Bulan Januari s/d Desember | J22: Pencairan Saat ini | K22: Sisa Anggaran
A23: 1 | C23: Beban Telepon/Listrik/Air/Wifi/Website | G23: --------------- | H23: --------------- | J23: --------------- | K23: ---------------
B24: 1.1 | C24: Biaya Telepon/Pulsa/Paket Data Hp Operasional | G24: 12000000 | H24: =JANUARI!H71+JANUARI!J71 -> 0 | J24: 0 | K24: =G24-H24-J24 -> 12000000
B25: 1.2 | C25: Biaya Air | G25: 18000000 | H25: =JANUARI!H72+JANUARI!J72 -> 1192745 | J25: 0 | K25: =G25-H25-J25 -> 16807255
B26: 1.3 | C26: Biaya Listrik | G26: 80000000 | H26: =JANUARI!H73+JANUARI!J73 -> 4273340 | J26: 0 | K26: =G26-H26-J26 -> 75726660
B27: 1.4 | C27: Biaya Wifi/Internet | G27: 20400000 | H27: =JANUARI!H74+JANUARI!J74 -> 904100 | J27: 0 | K27: =G27-H27-J27 -> 19495900
B28: 1.5 | C28: Biaya Website dan Aplikasi | G28: 50000000 | H28: =JANUARI!H75+JANUARI!J75 -> 61869180 | J28: 500000 | K28: =G28-H28-J28 -> -12369180
C29: JUMLAH | G29: =SUM(G23:G28) -> 180400000 | H29: =SUM(H23:H28) -> 68239365 | J29: =SUM(J23:J28) -> 500000 | K29: =SUM(K23:K28) -> 111660635
A31: Jumlah Yang Diminta | D31: : | E31: =J29 -> 500000
A32: PPN | D32: :
A33: PPh Psl 21/22/23/4(2) | D33: :
A34: Jumlah Potongan | D34: : | E34: =E32+E33 -> 0
A36: Jumlah yang dibayarkan | D36: : | E36: =E31-E34 -> 500000
E37: =PROPER(IF(E36=0,"nol",IF(E36<0,"minus ","")&SUBSTITUTE(TRIM(SUBSTITUTE(SUBSTITUTE(SUBSTITUTE(SUBSTITUTE(SUBSTITUTE(SUBSTITUTE(SUBSTITUTE(SUBSTITUTE(SUBSTITUTE(SUBSTITUTE(SUBSTITUTE(SUBSTITUTE(SUBSTITUTE(SUBSTITUTE(SUBSTITUTE(SUBSTITUTE(SUBSTITUTE(SUBSTITUTE(SUBSTITUTE(SUBSTITUTE(SUBSTITUTE(SUBSTITUTE(SUBSTITUTE(SUBSTITUTE(IF(--MID(TEXT(ABS(E36),"000000000000000"),1,3)=0,"",MID(TEXT(ABS(E36),"000000000000000"),1,1)&" ratus "&MID(TEXT(ABS(E36),"000000000000000"),2,1)&" puluh "&MID(TEXT(ABS(E36),"000000000000000"),3,1)&" trilyun ")&IF(--MID(TEXT(ABS(E36),"000000000000000"),4,3)=0,"",MID(TEXT(ABS(E36),"000000000000000"),4,1)&" ratus "&MID(TEXT(ABS(E36),"000000000000000"),5,1)&" puluh "&MID(TEXT(ABS(E36),"000000000000000"),6,1)&" milyar ")&IF(--MID(TEXT(ABS(E36),"000000000000000"),7,3)=0,"",MID(TEXT(ABS(E36),"000000000000000"),7,1)&" ratus "&MID(TEXT(ABS(E36),"000000000000000"),8,1)&" puluh "&MID(TEXT(ABS(E36),"000000000000000"),9,1)&" juta ")&IF(--MID(TEXT(ABS(E36),"000000000000000"),10,3)=0,"",IF(--MID(TEXT(ABS(E36),"000000000000000"),10,3)=1,"*",MID(TEXT(ABS(E36),"000000000000000"),10,1)&" ratus "&MID(TEXT(ABS(E36),"000000000000000"),11,1)&" puluh ")&MID(TEXT(ABS(E36),"000000000000000"),12,1)&" ribu ")&IF(--MID(TEXT(ABS(E36),"000000000000000"),13,3)=0,"",MID(TEXT(ABS(E36),"000000000000000"),13,1)&" ratus "&MID(TEXT(ABS(E36),"000000000000000"),14,1)&" puluh "&MID(TEXT(ABS(E36),"000000000000000"),15,1)),1,"satu"),2,"dua"),3,"tiga"),4,"empat"),5,"lima"),6,"enam"),7,"tujuh"),8,"delapan"),9,"sembilan"),"0 ratus",""),"0 puluh",""),"satu puluh 0","sepuluh"),"satu puluh satu","sebelas"),"satu puluh dua","duabelas"),"satu puluh tiga","tigabelas"),"satu puluh empat","empatbelas"),"satu puluh lima","limabelas"),"satu puluh enam","enambelas"),"satu puluh tujuh","tujuhbelas"),"satu puluh delapan","delapanbelas"),"satu puluh sembilan","sembilanbelas"),"satu ratus","seratus"),"*satu ribu","seribu"),0,""))," "," "))&" Rupiah") -> Lima Ratus Ribu Rupiah
J40: Banjarmasin, 03 Februari 2026
A41: MENGETAHUI | J41: YANG MEMBUAT
A46: IRNA WAHYUNI N. | J46: M. ZULKIFLI
A55: NOTA PENCIRAN DANA (NPD)
A56: Nomor : 045/DIV-KEU/PPB/II/2026
A57: BENDAHARA PENGELUARAN
A58: PERUMDA PASAR BANJARMASIN
A59: Supaya Mencairkan Dana
A61: 1. Sub Kegiatan | D61: : | E61: Beban Umum & Keuangan
A62: 2. Nomor | D62: : | E62: 2.1.4
A63: 3. Tahun Anggaran | D63: : | E63: 2026
A64: 4. Jumlah Yang Diminta | D64: : | E64: =J76 -> 7006427
D65: : | E65: =PROPER(IF(E64=0,"nol",IF(E64<0,"minus ","")&SUBSTITUTE(TRIM(SUBSTITUTE(SUBSTITUTE(SUBSTITUTE(SUBSTITUTE(SUBSTITUTE(SUBSTITUTE(SUBSTITUTE(SUBSTITUTE(SUBSTITUTE(SUBSTITUTE(SUBSTITUTE(SUBSTITUTE(SUBSTITUTE(SUBSTITUTE(SUBSTITUTE(SUBSTITUTE(SUBSTITUTE(SUBSTITUTE(SUBSTITUTE(SUBSTITUTE(SUBSTITUTE(SUBSTITUTE(SUBSTITUTE(SUBSTITUTE(IF(--MID(TEXT(ABS(E64),"000000000000000"),1,3)=0,"",MID(TEXT(ABS(E64),"000000000000000"),1,1)&" ratus "&MID(TEXT(ABS(E64),"000000000000000"),2,1)&" puluh "&MID(TEXT(ABS(E64),"000000000000000"),3,1)&" trilyun ")&IF(--MID(TEXT(ABS(E64),"000000000000000"),4,3)=0,"",MID(TEXT(ABS(E64),"000000000000000"),4,1)&" ratus "&MID(TEXT(ABS(E64),"000000000000000"),5,1)&" puluh "&MID(TEXT(ABS(E64),"000000000000000"),6,1)&" milyar ")&IF(--MID(TEXT(ABS(E64),"000000000000000"),7,3)=0,"",MID(TEXT(ABS(E64),"000000000000000"),7,1)&" ratus "&MID(TEXT(ABS(E64),"000000000000000"),8,1)&" puluh "&MID(TEXT(ABS(E64),"000000000000000"),9,1)&" juta ")&IF(--MID(TEXT(ABS(E64),"000000000000000"),10,3)=0,"",IF(--MID(TEXT(ABS(E64),"000000000000000"),10,3)=1,"*",MID(TEXT(ABS(E64),"000000000000000"),10,1)&" ratus "&MID(TEXT(ABS(E64),"000000000000000"),11,1)&" puluh ")&MID(TEXT(ABS(E64),"000000000000000"),12,1)&" ribu ")&IF(--MID(TEXT(ABS(E64),"000000000000000"),13,3)=0,"",MID(TEXT(ABS(E64),"000000000000000"),13,1)&" ratus "&MID(TEXT(ABS(E64),"000000000000000"),14,1)&" puluh "&MID(TEXT(ABS(E64),"000000000000000"),15,1)),1,"satu"),2,"dua"),3,"tiga"),4,"empat"),5,"lima"),6,"enam"),7,"tujuh"),8,"delapan"),9,"sembilan"),"0 ratus",""),"0 puluh",""),"satu puluh 0","sepuluh"),"satu puluh satu","sebelas"),"satu puluh dua","duabelas"),"satu puluh tiga","tigabelas"),"satu puluh empat","empatbelas"),"satu puluh lima","limabelas"),"satu puluh enam","enambelas"),"satu puluh tujuh","tujuhbelas"),"satu puluh delapan","delapanbelas"),"satu puluh sembilan","sembilanbelas"),"satu ratus","seratus"),"*satu ribu","seribu"),0,""))," "," "))&" Rupiah") -> Tujuh Juta Enam Ribu Empat Ratus Dua Puluh Tujuh Rupiah
A68: Pembebanan Pada Kode Rekening
A69: NO | B69: Kode | C69: Uraian | G69: Anggaran | H69: Akumulasi Pencairan dana Bulan Januari s/d Desember | J69: Pencairan Saat ini | K69: Sisa Anggaran
...

Sheet MARET
A8: NOTA PENCIRAN DANA (NPD)
A9: Nomor : 034/DIV-KEU/PPB/III/2026
A10: BENDAHARA PENGELUARAN
A11: PERUMDA PASAR BANJARMASIN
A12: Supaya Mencairkan Dana
A14: 1. Sub Kegiatan | D14: : | E14: Beban Umum & Keuangan
A15: 2. Nomor | D15: : | E15: 2.1.4
A16: 3. Tahun Anggaran | D16: : | E16: 2026
A17: 4. Jumlah Yang Diminta | D17: : | E17: =J29 -> 5833332
D18: : | E18: =PROPER(IF(E17=0,"nol",IF(E17<0,"minus ","")&SUBSTITUTE(TRIM(SUBSTITUTE(SUBSTITUTE(SUBSTITUTE(SUBSTITUTE(SUBSTITUTE(SUBSTITUTE(SUBSTITUTE(SUBSTITUTE(SUBSTITUTE(SUBSTITUTE(SUBSTITUTE(SUBSTITUTE(SUBSTITUTE(SUBSTITUTE(SUBSTITUTE(SUBSTITUTE(SUBSTITUTE(SUBSTITUTE(SUBSTITUTE(SUBSTITUTE(SUBSTITUTE(SUBSTITUTE(SUBSTITUTE(SUBSTITUTE(IF(--MID(TEXT(ABS(E17),"000000000000000"),1,3)=0,"",MID(TEXT(ABS(E17),"000000000000000"),1,1)&" ratus "&MID(TEXT(ABS(E17),"000000000000000"),2,1)&" puluh "&MID(TEXT(ABS(E17),"000000000000000"),3,1)&" trilyun ")&IF(--MID(TEXT(ABS(E17),"000000000000000"),4,3)=0,"",MID(TEXT(ABS(E17),"000000000000000"),4,1)&" ratus "&MID(TEXT(ABS(E17),"000000000000000"),5,1)&" puluh "&MID(TEXT(ABS(E17),"000000000000000"),6,1)&" milyar ")&IF(--MID(TEXT(ABS(E17),"000000000000000"),7,3)=0,"",MID(TEXT(ABS(E17),"000000000000000"),7,1)&" ratus "&MID(TEXT(ABS(E17),"000000000000000"),8,1)&" puluh "&MID(TEXT(ABS(E17),"000000000000000"),9,1)&" juta ")&IF(--MID(TEXT(ABS(E17),"000000000000000"),10,3)=0,"",IF(--MID(TEXT(ABS(E17),"000000000000000"),10,3)=1,"*",MID(TEXT(ABS(E17),"000000000000000"),10,1)&" ratus "&MID(TEXT(ABS(E17),"000000000000000"),11,1)&" puluh ")&MID(TEXT(ABS(E17),"000000000000000"),12,1)&" ribu ")&IF(--MID(TEXT(ABS(E17),"000000000000000"),13,3)=0,"",MID(TEXT(ABS(E17),"000000000000000"),13,1)&" ratus "&MID(TEXT(ABS(E17),"000000000000000"),14,1)&" puluh "&MID(TEXT(ABS(E17),"000000000000000"),15,1)),1,"satu"),2,"dua"),3,"tiga"),4,"empat"),5,"lima"),6,"enam"),7,"tujuh"),8,"delapan"),9,"sembilan"),"0 ratus",""),"0 puluh",""),"satu puluh 0","sepuluh"),"satu puluh satu","sebelas"),"satu puluh dua","duabelas"),"satu puluh tiga","tigabelas"),"satu puluh empat","empatbelas"),"satu puluh lima","limabelas"),"satu puluh enam","enambelas"),"satu puluh tujuh","tujuhbelas"),"satu puluh delapan","delapanbelas"),"satu puluh sembilan","sembilanbelas"),"satu ratus","seratus"),"*satu ribu","seribu"),0,""))," "," "))&" Rupiah") -> Lima Juta Delapan Ratus Tiga Puluh Tiga Ribu Tiga Ratus Tiga Puluh Dua Rupiah
A21: Pembebanan Pada Kode Rekening
A22: NO | B22: Kode | C22: Uraian | G22: Anggaran | H22: Akumulasi Pencairan dana Bulan Januari s/d Desember | J22: Pencairan Saat ini | K22: Sisa Anggaran
A23: 1 | C23: Beban Telepon/Listrik/Air/Wifi/Website | G23: --------------- | H23: --------------- | J23: --------------- | K23: ---------------
B24: 1.1 | C24: Biaya Telepon/Pulsa/Paket Data Hp Operasional | G24: 12000000 | H24: =FEBRUARI!H165+FEBRUARI!J165 -> 0 | J24: 0 | K24: =G24-H24-J24 -> 12000000
B25: 1.2 | C25: Biaya Air | G25: 18000000 | H25: =FEBRUARI!H166+FEBRUARI!J166 -> 2224121 | J25: 1252278 | K25: =G25-H25-J25 -> 14523601
B26: 1.3 | C26: Biaya Listrik | G26: 80000000 | H26: =FEBRUARI!H167+FEBRUARI!J167 -> 10072267 | J26: 3187164 | K26: =G26-H26-J26 -> 66740569
B27: 1.4 | C27: Biaya Wifi/Internet | G27: 20400000 | H27: =FEBRUARI!H168+FEBRUARI!J168 -> 2083724 | J27: 1393890 | K27: =G27-H27-J27 -> 16922386
B28: 1.5 | C28: Biaya Website dan Aplikasi | G28: 50000000 | H28: =FEBRUARI!H169+FEBRUARI!J169 -> 64265180 | J28: 0 | K28: =G28-H28-J28 -> -14265180
C29: JUMLAH | G29: =SUM(G23:G28) -> 180400000 | H29: =SUM(H23:H28) -> 78645292 | J29: =SUM(J23:J28) -> 5833332 | K29: =SUM(K23:K28) -> 95921376
A31: Jumlah Yang Diminta | D31: : | E31: =J29 -> 5833332
A32: PPN | D32: :
A33: PPh Psl 21/22/23/4(2) | D33: :
A34: Jumlah Potongan | D34: : | E34: =E32+E33 -> 0
A36: Jumlah yang dibayarkan | D36: : | E36: =E31-E34 -> 5833332
E37: =PROPER(IF(E36=0,"nol",IF(E36<0,"minus ","")&SUBSTITUTE(TRIM(SUBSTITUTE(SUBSTITUTE(SUBSTITUTE(SUBSTITUTE(SUBSTITUTE(SUBSTITUTE(SUBSTITUTE(SUBSTITUTE(SUBSTITUTE(SUBSTITUTE(SUBSTITUTE(SUBSTITUTE(SUBSTITUTE(SUBSTITUTE(SUBSTITUTE(SUBSTITUTE(SUBSTITUTE(SUBSTITUTE(SUBSTITUTE(SUBSTITUTE(SUBSTITUTE(SUBSTITUTE(SUBSTITUTE(SUBSTITUTE(IF(--MID(TEXT(ABS(E36),"000000000000000"),1,3)=0,"",MID(TEXT(ABS(E36),"000000000000000"),1,1)&" ratus "&MID(TEXT(ABS(E36),"000000000000000"),2,1)&" puluh "&MID(TEXT(ABS(E36),"000000000000000"),3,1)&" trilyun ")&IF(--MID(TEXT(ABS(E36),"000000000000000"),4,3)=0,"",MID(TEXT(ABS(E36),"000000000000000"),4,1)&" ratus "&MID(TEXT(ABS(E36),"000000000000000"),5,1)&" puluh "&MID(TEXT(ABS(E36),"000000000000000"),6,1)&" milyar ")&IF(--MID(TEXT(ABS(E36),"000000000000000"),7,3)=0,"",MID(TEXT(ABS(E36),"000000000000000"),7,1)&" ratus "&MID(TEXT(ABS(E36),"000000000000000"),8,1)&" puluh "&MID(TEXT(ABS(E36),"000000000000000"),9,1)&" juta ")&IF(--MID(TEXT(ABS(E36),"000000000000000"),10,3)=0,"",IF(--MID(TEXT(ABS(E36),"000000000000000"),10,3)=1,"*",MID(TEXT(ABS(E36),"000000000000000"),10,1)&" ratus "&MID(TEXT(ABS(E36),"000000000000000"),11,1)&" puluh ")&MID(TEXT(ABS(E36),"000000000000000"),12,1)&" ribu ")&IF(--MID(TEXT(ABS(E36),"000000000000000"),13,3)=0,"",MID(TEXT(ABS(E36),"000000000000000"),13,1)&" ratus "&MID(TEXT(ABS(E36),"000000000000000"),14,1)&" puluh "&MID(TEXT(ABS(E36),"000000000000000"),15,1)),1,"satu"),2,"dua"),3,"tiga"),4,"empat"),5,"lima"),6,"enam"),7,"tujuh"),8,"delapan"),9,"sembilan"),"0 ratus",""),"0 puluh",""),"satu puluh 0","sepuluh"),"satu puluh satu","sebelas"),"satu puluh dua","duabelas"),"satu puluh tiga","tigabelas"),"satu puluh empat","empatbelas"),"satu puluh lima","limabelas"),"satu puluh enam","enambelas"),"satu puluh tujuh","tujuhbelas"),"satu puluh delapan","delapanbelas"),"satu puluh sembilan","sembilanbelas"),"satu ratus","seratus"),"*satu ribu","seribu"),0,""))," "," "))&" Rupiah") -> Lima Juta Delapan Ratus Tiga Puluh Tiga Ribu Tiga Ratus Tiga Puluh Dua Rupiah
J40: Banjarmasin, 16 Maret 2026
A41: MENGETAHUI | J41: YANG MEMBUAT
A46: IRNA WAHYUNI N. | J46: M. ZULKIFLI
A55: NOTA PENCIRAN DANA (NPD)
A56: Nomor : 045/DIV-KEU/PPB/II/2026
A57: BENDAHARA PENGELUARAN
A58: PERUMDA PASAR BANJARMASIN
A59: Supaya Mencairkan Dana
A61: 1. Sub Kegiatan | D61: : | E61: Beban Umum & Keuangan
A62: 2. Nomor | D62: : | E62: 2.1.4
A63: 3. Tahun Anggaran | D63: : | E63: 2026
A64: 4. Jumlah Yang Diminta | D64: : | E64: =J76 -> 7006427
D65: : | E65: =PROPER(IF(E64=0,"nol",IF(E64<0,"minus ","")&SUBSTITUTE(TRIM(SUBSTITUTE(SUBSTITUTE(SUBSTITUTE(SUBSTITUTE(SUBSTITUTE(SUBSTITUTE(SUBSTITUTE(SUBSTITUTE(SUBSTITUTE(SUBSTITUTE(SUBSTITUTE(SUBSTITUTE(SUBSTITUTE(SUBSTITUTE(SUBSTITUTE(SUBSTITUTE(SUBSTITUTE(SUBSTITUTE(SUBSTITUTE(SUBSTITUTE(SUBSTITUTE(SUBSTITUTE(SUBSTITUTE(SUBSTITUTE(IF(--MID(TEXT(ABS(E64),"000000000000000"),1,3)=0,"",MID(TEXT(ABS(E64),"000000000000000"),1,1)&" ratus "&MID(TEXT(ABS(E64),"000000000000000"),2,1)&" puluh "&MID(TEXT(ABS(E64),"000000000000000"),3,1)&" trilyun ")&IF(--MID(TEXT(ABS(E64),"000000000000000"),4,3)=0,"",MID(TEXT(ABS(E64),"000000000000000"),4,1)&" ratus "&MID(TEXT(ABS(E64),"000000000000000"),5,1)&" puluh "&MID(TEXT(ABS(E64),"000000000000000"),6,1)&" milyar ")&IF(--MID(TEXT(ABS(E64),"000000000000000"),7,3)=0,"",MID(TEXT(ABS(E64),"000000000000000"),7,1)&" ratus "&MID(TEXT(ABS(E64),"000000000000000"),8,1)&" puluh "&MID(TEXT(ABS(E64),"000000000000000"),9,1)&" juta ")&IF(--MID(TEXT(ABS(E64),"000000000000000"),10,3)=0,"",IF(--MID(TEXT(ABS(E64),"000000000000000"),10,3)=1,"*",MID(TEXT(ABS(E64),"000000000000000"),10,1)&" ratus "&MID(TEXT(ABS(E64),"000000000000000"),11,1)&" puluh ")&MID(TEXT(ABS(E64),"000000000000000"),12,1)&" ribu ")&IF(--MID(TEXT(ABS(E64),"000000000000000"),13,3)=0,"",MID(TEXT(ABS(E64),"000000000000000"),13,1)&" ratus "&MID(TEXT(ABS(E64),"000000000000000"),14,1)&" puluh "&MID(TEXT(ABS(E64),"000000000000000"),15,1)),1,"satu"),2,"dua"),3,"tiga"),4,"empat"),5,"lima"),6,"enam"),7,"tujuh"),8,"delapan"),9,"sembilan"),"0 ratus",""),"0 puluh",""),"satu puluh 0","sepuluh"),"satu puluh satu","sebelas"),"satu puluh dua","duabelas"),"satu puluh tiga","tigabelas"),"satu puluh empat","empatbelas"),"satu puluh lima","limabelas"),"satu puluh enam","enambelas"),"satu puluh tujuh","tujuhbelas"),"satu puluh delapan","delapanbelas"),"satu puluh sembilan","sembilanbelas"),"satu ratus","seratus"),"*satu ribu","seribu"),0,""))," "," "))&" Rupiah") -> Tujuh Juta Enam Ribu Empat Ratus Dua Puluh Tujuh Rupiah
A68: Pembebanan Pada Kode Rekening
A69: NO | B69: Kode | C69: Uraian | G69: Anggaran | H69: Akumulasi Pencairan dana Bulan Januari s/d Desember | J69: Pencairan Saat ini | K69: Sisa Anggaran
...
