Workbook

Sheet JANUARI
A8: NOTA PENCIRAN DANA (NPD)
A9: Nomor : 039/DIV-KEU/PPB/I/2026
A10: BENDAHARA PENGELUARAN
A11: PERUMDA PASAR BANJARMASIN
A12: Supaya Mencairkan Dana
A14: 1. Sub Kegiatan | D14: : | E14: Beban Umum & Keuangan
A15: 2. Nomor | D15: : | E15: 2.1.4
A16: 3. Tahun Anggaran | D16: : | E16: 2026
A17: 4. Jumlah Yang Diminta | D17: : | E17: =J29 -> 0
D18: : | E18: =PROPER(IF(E17=0,"nol",IF(E17<0,"minus ","")&SUBSTITUTE(TRIM(SUBSTITUTE(SUBSTITUTE(SUBSTITUTE(SUBSTITUTE(SUBSTITUTE(SUBSTITUTE(SUBSTITUTE(SUBSTITUTE(SUBSTITUTE(SUBSTITUTE(SUBSTITUTE(SUBSTITUTE(SUBSTITUTE(SUBSTITUTE(SUBSTITUTE(SUBSTITUTE(SUBSTITUTE(SUBSTITUTE(SUBSTITUTE(SUBSTITUTE(SUBSTITUTE(SUBSTITUTE(SUBSTITUTE(SUBSTITUTE(IF(--MID(TEXT(ABS(E17),"000000000000000"),1,3)=0,"",MID(TEXT(ABS(E17),"000000000000000"),1,1)&" ratus "&MID(TEXT(ABS(E17),"000000000000000"),2,1)&" puluh "&MID(TEXT(ABS(E17),"000000000000000"),3,1)&" trilyun ")&IF(--MID(TEXT(ABS(E17),"000000000000000"),4,3)=0,"",MID(TEXT(ABS(E17),"000000000000000"),4,1)&" ratus "&MID(TEXT(ABS(E17),"000000000000000"),5,1)&" puluh "&MID(TEXT(ABS(E17),"000000000000000"),6,1)&" milyar ")&IF(--MID(TEXT(ABS(E17),"000000000000000"),7,3)=0,"",MID(TEXT(ABS(E17),"000000000000000"),7,1)&" ratus "&MID(TEXT(ABS(E17),"000000000000000"),8,1)&" puluh "&MID(TEXT(ABS(E17),"000000000000000"),9,1)&" juta ")&IF(--MID(TEXT(ABS(E17),"000000000000000"),10,3)=0,"",IF(--MID(TEXT(ABS(E17),"000000000000000"),10,3)=1,"*",MID(TEXT(ABS(E17),"000000000000000"),10,1)&" ratus "&MID(TEXT(ABS(E17),"000000000000000"),11,1)&" puluh ")&MID(TEXT(ABS(E17),"000000000000000"),12,1)&" ribu ")&IF(--MID(TEXT(ABS(E17),"000000000000000"),13,3)=0,"",MID(TEXT(ABS(E17),"000000000000000"),13,1)&" ratus "&MID(TEXT(ABS(E17),"000000000000000"),14,1)&" puluh "&MID(TEXT(ABS(E17),"000000000000000"),15,1)),1,"satu"),2,"dua"),3,"tiga"),4,"empat"),5,"lima"),6,"enam"),7,"tujuh"),8,"delapan"),9,"sembilan"),"0 ratus",""),"0 puluh",""),"satu puluh 0","sepuluh"),"satu puluh satu","sebelas"),"satu puluh dua","duabelas"),"satu puluh tiga","tigabelas"),"satu puluh empat","empatbelas"),"satu puluh lima","limabelas"),"satu puluh enam","enambelas"),"satu puluh tujuh","tujuhbelas"),"satu puluh delapan","delapanbelas"),"satu puluh sembilan","sembilanbelas"),"satu ratus","seratus"),"*satu ribu","seribu"),0,""))," "," "))&" Rupiah") -> Nol Rupiah
A21: Pembebanan Pada Kode Rekening
A22: NO | B22: Kode | C22: Uraian | G22: Anggaran | H22: Akumulasi Pencairan dana Bulan Januari s/d Desember | J22: Pencairan Saat ini | K22: Sisa Anggaran
A23: 1 | C23: Beban Jasa Profesional/Konsultan/Tenaga Ahli | G23: --------------- | H23: --------------- | J23: --------------- | K23: ---------------
B24: 1.1 | C24: Beban Konsultan Rencana Bisnis | G24: 0 | H24: 0 | J24: 0 | K24: =G24-H24-J24 -> 0
B25: 1.2 | C25: Beban Seleksi Pegawai | G25: 50000000 | H25: 0 | J25: 0 | K25: =G25-H25-J25 -> 50000000
B26: 1.3 | C26: Beban Audit Laporan Keuangan/Pendampingan KAP | G26: 100000000 | H26: 0 | J26: 0 | K26: =G26-H26-J26 -> 100000000
B27: 1.4 | C27: Beban Kajian Penyesuaian Tarif | G27: 100000000 | H27: 0 | J27: 0 | K27: =G27-H27-J27 -> 100000000
B28: 1.5 | C28: Beban Pendataan Pedagang | G28: 44000000 | H28: 0 | J28: 944000 | K28: =G28-H28-J28 -> 43056000
C29: JUMLAH | G29: =SUM(G23:G28) -> 294000000 | H29: =SUM(H23:H28) -> 0 | J29: =SUM(J23:J27) -> 0 | K29: =SUM(K23:K27) -> 250000000
A31: Jumlah Yang Diminta | D31: : | E31: =J29 -> 0
A32: PPN | D32: :
A33: PPh Psl 21/22/23/4(2) | D33: :
A34: Jumlah Potongan | D34: : | E34: =E32+E33 -> 0
A36: Jumlah yang dibayarkan | D36: : | E36: =E31-E34 -> 0
E37: =PROPER(IF(E36=0,"nol",IF(E36<0,"minus ","")&SUBSTITUTE(TRIM(SUBSTITUTE(SUBSTITUTE(SUBSTITUTE(SUBSTITUTE(SUBSTITUTE(SUBSTITUTE(SUBSTITUTE(SUBSTITUTE(SUBSTITUTE(SUBSTITUTE(SUBSTITUTE(SUBSTITUTE(SUBSTITUTE(SUBSTITUTE(SUBSTITUTE(SUBSTITUTE(SUBSTITUTE(SUBSTITUTE(SUBSTITUTE(SUBSTITUTE(SUBSTITUTE(SUBSTITUTE(SUBSTITUTE(SUBSTITUTE(IF(--MID(TEXT(ABS(E36),"000000000000000"),1,3)=0,"",MID(TEXT(ABS(E36),"000000000000000"),1,1)&" ratus "&MID(TEXT(ABS(E36),"000000000000000"),2,1)&" puluh "&MID(TEXT(ABS(E36),"000000000000000"),3,1)&" trilyun ")&IF(--MID(TEXT(ABS(E36),"000000000000000"),4,3)=0,"",MID(TEXT(ABS(E36),"000000000000000"),4,1)&" ratus "&MID(TEXT(ABS(E36),"000000000000000"),5,1)&" puluh "&MID(TEXT(ABS(E36),"000000000000000"),6,1)&" milyar ")&IF(--MID(TEXT(ABS(E36),"000000000000000"),7,3)=0,"",MID(TEXT(ABS(E36),"000000000000000"),7,1)&" ratus "&MID(TEXT(ABS(E36),"000000000000000"),8,1)&" puluh "&MID(TEXT(ABS(E36),"000000000000000"),9,1)&" juta ")&IF(--MID(TEXT(ABS(E36),"000000000000000"),10,3)=0,"",IF(--MID(TEXT(ABS(E36),"000000000000000"),10,3)=1,"*",MID(TEXT(ABS(E36),"000000000000000"),10,1)&" ratus "&MID(TEXT(ABS(E36),"000000000000000"),11,1)&" puluh ")&MID(TEXT(ABS(E36),"000000000000000"),12,1)&" ribu ")&IF(--MID(TEXT(ABS(E36),"000000000000000"),13,3)=0,"",MID(TEXT(ABS(E36),"000000000000000"),13,1)&" ratus "&MID(TEXT(ABS(E36),"000000000000000"),14,1)&" puluh "&MID(TEXT(ABS(E36),"000000000000000"),15,1)),1,"satu"),2,"dua"),3,"tiga"),4,"empat"),5,"lima"),6,"enam"),7,"tujuh"),8,"delapan"),9,"sembilan"),"0 ratus",""),"0 puluh",""),"satu puluh 0","sepuluh"),"satu puluh satu","sebelas"),"satu puluh dua","duabelas"),"satu puluh tiga","tigabelas"),"satu puluh empat","empatbelas"),"satu puluh lima","limabelas"),"satu puluh enam","enambelas"),"satu puluh tujuh","tujuhbelas"),"satu puluh delapan","delapanbelas"),"satu puluh sembilan","sembilanbelas"),"satu ratus","seratus"),"*satu ribu","seribu"),0,""))," "," "))&" Rupiah") -> Nol Rupiah
J40: Banjarmasin, 02 Januari 2026
A41: MENGETAHUI | J41: YANG MEMBUAT
A46: IRNA WAHYUNI N. | J46: M. ZULKIFLI
A55: NOTA PENCIRAN DANA (NPD)
A56: Nomor : 68/DIV-KEU/PPB/I/2026
A57: BENDAHARA PENGELUARAN
A58: PERUMDA PASAR BANJARMASIN
A59: Supaya Mencairkan Dana
A61: 1. Sub Kegiatan | D61: : | E61: Beban Umum & Keuangan
A62: 2. Nomor | D62: : | E62: 2.1.4
A63: 3. Tahun Anggaran | D63: : | E63: 2026
A64: 4. Jumlah Yang Diminta | D64: : | E64: =J76 -> 42500000
D65: : | E65: =PROPER(IF(E64=0,"nol",IF(E64<0,"minus ","")&SUBSTITUTE(TRIM(SUBSTITUTE(SUBSTITUTE(SUBSTITUTE(SUBSTITUTE(SUBSTITUTE(SUBSTITUTE(SUBSTITUTE(SUBSTITUTE(SUBSTITUTE(SUBSTITUTE(SUBSTITUTE(SUBSTITUTE(SUBSTITUTE(SUBSTITUTE(SUBSTITUTE(SUBSTITUTE(SUBSTITUTE(SUBSTITUTE(SUBSTITUTE(SUBSTITUTE(SUBSTITUTE(SUBSTITUTE(SUBSTITUTE(SUBSTITUTE(IF(--MID(TEXT(ABS(E64),"000000000000000"),1,3)=0,"",MID(TEXT(ABS(E64),"000000000000000"),1,1)&" ratus "&MID(TEXT(ABS(E64),"000000000000000"),2,1)&" puluh "&MID(TEXT(ABS(E64),"000000000000000"),3,1)&" trilyun ")&IF(--MID(TEXT(ABS(E64),"000000000000000"),4,3)=0,"",MID(TEXT(ABS(E64),"000000000000000"),4,1)&" ratus "&MID(TEXT(ABS(E64),"000000000000000"),5,1)&" puluh "&MID(TEXT(ABS(E64),"000000000000000"),6,1)&" milyar ")&IF(--MID(TEXT(ABS(E64),"000000000000000"),7,3)=0,"",MID(TEXT(ABS(E64),"000000000000000"),7,1)&" ratus "&MID(TEXT(ABS(E64),"000000000000000"),8,1)&" puluh "&MID(TEXT(ABS(E64),"000000000000000"),9,1)&" juta ")&IF(--MID(TEXT(ABS(E64),"000000000000000"),10,3)=0,"",IF(--MID(TEXT(ABS(E64),"000000000000000"),10,3)=1,"*",MID(TEXT(ABS(E64),"000000000000000"),10,1)&" ratus "&MID(TEXT(ABS(E64),"000000000000000"),11,1)&" puluh ")&MID(TEXT(ABS(E64),"000000000000000"),12,1)&" ribu ")&IF(--MID(TEXT(ABS(E64),"000000000000000"),13,3)=0,"",MID(TEXT(ABS(E64),"000000000000000"),13,1)&" ratus "&MID(TEXT(ABS(E64),"000000000000000"),14,1)&" puluh "&MID(TEXT(ABS(E64),"000000000000000"),15,1)),1,"satu"),2,"dua"),3,"tiga"),4,"empat"),5,"lima"),6,"enam"),7,"tujuh"),8,"delapan"),9,"sembilan"),"0 ratus",""),"0 puluh",""),"satu puluh 0","sepuluh"),"satu puluh satu","sebelas"),"satu puluh dua","duabelas"),"satu puluh tiga","tigabelas"),"satu puluh empat","empatbelas"),"satu puluh lima","limabelas"),"satu puluh enam","enambelas"),"satu puluh tujuh","tujuhbelas"),"satu puluh delapan","delapanbelas"),"satu puluh sembilan","sembilanbelas"),"satu ratus","seratus"),"*satu ribu","seribu"),0,""))," "," "))&" Rupiah") -> Empat Puluh Dua Juta Lima Ratus Ribu Rupiah
A68: Pembebanan Pada Kode Rekening
A69: NO | B69: Kode | C69: Uraian | G69: Anggaran | H69: Akumulasi Pencairan dana Bulan Januari s/d Desember | J69: Pencairan Saat ini | K69: Sisa Anggaran
...

Sheet MARET
A8: NOTA PENCIRAN DANA (NPD)
A9: Nomor : 008/DIV-KEU/PPB/III/2026
A10: BENDAHARA PENGELUARAN
A11: PERUMDA PASAR BANJARMASIN
A12: Supaya Mencairkan Dana
A14: 1. Sub Kegiatan | D14: : | E14: Beban Umum & Keuangan
A15: 2. Nomor | D15: : | E15: 2.1.4
A16: 3. Tahun Anggaran | D16: : | E16: 2026
A17: 4. Jumlah Yang Diminta | D17: : | E17: =J29 -> 460000
D18: : | E18: =PROPER(IF(E17=0,"nol",IF(E17<0,"minus ","")&SUBSTITUTE(TRIM(SUBSTITUTE(SUBSTITUTE(SUBSTITUTE(SUBSTITUTE(SUBSTITUTE(SUBSTITUTE(SUBSTITUTE(SUBSTITUTE(SUBSTITUTE(SUBSTITUTE(SUBSTITUTE(SUBSTITUTE(SUBSTITUTE(SUBSTITUTE(SUBSTITUTE(SUBSTITUTE(SUBSTITUTE(SUBSTITUTE(SUBSTITUTE(SUBSTITUTE(SUBSTITUTE(SUBSTITUTE(SUBSTITUTE(SUBSTITUTE(IF(--MID(TEXT(ABS(E17),"000000000000000"),1,3)=0,"",MID(TEXT(ABS(E17),"000000000000000"),1,1)&" ratus "&MID(TEXT(ABS(E17),"000000000000000"),2,1)&" puluh "&MID(TEXT(ABS(E17),"000000000000000"),3,1)&" trilyun ")&IF(--MID(TEXT(ABS(E17),"000000000000000"),4,3)=0,"",MID(TEXT(ABS(E17),"000000000000000"),4,1)&" ratus "&MID(TEXT(ABS(E17),"000000000000000"),5,1)&" puluh "&MID(TEXT(ABS(E17),"000000000000000"),6,1)&" milyar ")&IF(--MID(TEXT(ABS(E17),"000000000000000"),7,3)=0,"",MID(TEXT(ABS(E17),"000000000000000"),7,1)&" ratus "&MID(TEXT(ABS(E17),"000000000000000"),8,1)&" puluh "&MID(TEXT(ABS(E17),"000000000000000"),9,1)&" juta ")&IF(--MID(TEXT(ABS(E17),"000000000000000"),10,3)=0,"",IF(--MID(TEXT(ABS(E17),"000000000000000"),10,3)=1,"*",MID(TEXT(ABS(E17),"000000000000000"),10,1)&" ratus "&MID(TEXT(ABS(E17),"000000000000000"),11,1)&" puluh ")&MID(TEXT(ABS(E17),"000000000000000"),12,1)&" ribu ")&IF(--MID(TEXT(ABS(E17),"000000000000000"),13,3)=0,"",MID(TEXT(ABS(E17),"000000000000000"),13,1)&" ratus "&MID(TEXT(ABS(E17),"000000000000000"),14,1)&" puluh "&MID(TEXT(ABS(E17),"000000000000000"),15,1)),1,"satu"),2,"dua"),3,"tiga"),4,"empat"),5,"lima"),6,"enam"),7,"tujuh"),8,"delapan"),9,"sembilan"),"0 ratus",""),"0 puluh",""),"satu puluh 0","sepuluh"),"satu puluh satu","sebelas"),"satu puluh dua","duabelas"),"satu puluh tiga","tigabelas"),"satu puluh empat","empatbelas"),"satu puluh lima","limabelas"),"satu puluh enam","enambelas"),"satu puluh tujuh","tujuhbelas"),"satu puluh delapan","delapanbelas"),"satu puluh sembilan","sembilanbelas"),"satu ratus","seratus"),"*satu ribu","seribu"),0,""))," "," "))&" Rupiah") -> Empat Ratus Enam Puluh Ribu Rupiah
A21: Pembebanan Pada Kode Rekening
A22: NO | B22: Kode | C22: Uraian | G22: Anggaran | H22: Akumulasi Pencairan dana Bulan Januari s/d Desember | J22: Pencairan Saat ini | K22: Sisa Anggaran
A23: 1 | C23: Beban Jasa Profesional/Konsultan/Tenaga Ahli | G23: --------------- | H23: --------------- | J23: --------------- | K23: ---------------
B24: 1.1 | C24: Beban Konsultan Rencana Bisnis | G24: 0 | H24: =JANUARI!H71+JANUARI!J71 -> 0 | J24: 0 | K24: =G24-H24-J24 -> 0
B25: 1.2 | C25: Beban Seleksi Pegawai | G25: 50000000 | H25: =JANUARI!H72+JANUARI!J72 -> 0 | J25: 0 | K25: =G25-H25-J25 -> 50000000
B26: 1.3 | C26: Beban Audit Laporan Keuangan/Pendampingan KAP | G26: 100000000 | H26: =JANUARI!H73+JANUARI!J73 -> 42500000 | J26: 460000 | K26: =G26-H26-J26 -> 57040000
B27: 1.4 | C27: Beban Kajian Penyesuaian Tarif | G27: 100000000 | H27: =JANUARI!H74+JANUARI!J74 -> 0 | J27: 0 | K27: =G27-H27-J27 -> 100000000
B28: 1.5 | C28: Beban Pendataan Pedagang | G28: 44000000 | H28: =JANUARI!H75+JANUARI!J75 -> 944000 | J28: 0 | K28: =G28-H28-J28 -> 43056000
C29: JUMLAH | G29: =SUM(G23:G28) -> 294000000 | H29: =SUM(H23:H28) -> 43444000 | J29: =SUM(J23:J27) -> 460000 | K29: =SUM(K23:K27) -> 207040000
A31: Jumlah Yang Diminta | D31: : | E31: =J29 -> 460000
A32: PPN | D32: :
A33: PPh Psl 21/22/23/4(2) | D33: :
A34: Jumlah Potongan | D34: : | E34: =E32+E33 -> 0
A36: Jumlah yang dibayarkan | D36: : | E36: =E31-E34 -> 460000
E37: =PROPER(IF(E36=0,"nol",IF(E36<0,"minus ","")&SUBSTITUTE(TRIM(SUBSTITUTE(SUBSTITUTE(SUBSTITUTE(SUBSTITUTE(SUBSTITUTE(SUBSTITUTE(SUBSTITUTE(SUBSTITUTE(SUBSTITUTE(SUBSTITUTE(SUBSTITUTE(SUBSTITUTE(SUBSTITUTE(SUBSTITUTE(SUBSTITUTE(SUBSTITUTE(SUBSTITUTE(SUBSTITUTE(SUBSTITUTE(SUBSTITUTE(SUBSTITUTE(SUBSTITUTE(SUBSTITUTE(SUBSTITUTE(IF(--MID(TEXT(ABS(E36),"000000000000000"),1,3)=0,"",MID(TEXT(ABS(E36),"000000000000000"),1,1)&" ratus "&MID(TEXT(ABS(E36),"000000000000000"),2,1)&" puluh "&MID(TEXT(ABS(E36),"000000000000000"),3,1)&" trilyun ")&IF(--MID(TEXT(ABS(E36),"000000000000000"),4,3)=0,"",MID(TEXT(ABS(E36),"000000000000000"),4,1)&" ratus "&MID(TEXT(ABS(E36),"000000000000000"),5,1)&" puluh "&MID(TEXT(ABS(E36),"000000000000000"),6,1)&" milyar ")&IF(--MID(TEXT(ABS(E36),"000000000000000"),7,3)=0,"",MID(TEXT(ABS(E36),"000000000000000"),7,1)&" ratus "&MID(TEXT(ABS(E36),"000000000000000"),8,1)&" puluh "&MID(TEXT(ABS(E36),"000000000000000"),9,1)&" juta ")&IF(--MID(TEXT(ABS(E36),"000000000000000"),10,3)=0,"",IF(--MID(TEXT(ABS(E36),"000000000000000"),10,3)=1,"*",MID(TEXT(ABS(E36),"000000000000000"),10,1)&" ratus "&MID(TEXT(ABS(E36),"000000000000000"),11,1)&" puluh ")&MID(TEXT(ABS(E36),"000000000000000"),12,1)&" ribu ")&IF(--MID(TEXT(ABS(E36),"000000000000000"),13,3)=0,"",MID(TEXT(ABS(E36),"000000000000000"),13,1)&" ratus "&MID(TEXT(ABS(E36),"000000000000000"),14,1)&" puluh "&MID(TEXT(ABS(E36),"000000000000000"),15,1)),1,"satu"),2,"dua"),3,"tiga"),4,"empat"),5,"lima"),6,"enam"),7,"tujuh"),8,"delapan"),9,"sembilan"),"0 ratus",""),"0 puluh",""),"satu puluh 0","sepuluh"),"satu puluh satu","sebelas"),"satu puluh dua","duabelas"),"satu puluh tiga","tigabelas"),"satu puluh empat","empatbelas"),"satu puluh lima","limabelas"),"satu puluh enam","enambelas"),"satu puluh tujuh","tujuhbelas"),"satu puluh delapan","delapanbelas"),"satu puluh sembilan","sembilanbelas"),"satu ratus","seratus"),"*satu ribu","seribu"),0,""))," "," "))&" Rupiah") -> Empat Ratus Enam Puluh Ribu Rupiah
J40: Banjarmasin, 03 Maret 2026
A41: MENGETAHUI | J41: YANG MEMBUAT
A46: IRNA WAHYUNI N. | J46: M. ZULKIFLI
A55: NOTA PENCIRAN DANA (NPD)
A56: Nomor : 029/DIV-KEU/PPB/III/2026
A57: BENDAHARA PENGELUARAN
A58: PERUMDA PASAR BANJARMASIN
A59: Supaya Mencairkan Dana
A61: 1. Sub Kegiatan | D61: : | E61: Beban Umum & Keuangan
A62: 2. Nomor | D62: : | E62: 2.1.4
A63: 3. Tahun Anggaran | D63: : | E63: 2026
A64: 4. Jumlah Yang Diminta | D64: : | E64: =J76 -> 42500000
D65: : | E65: =PROPER(IF(E64=0,"nol",IF(E64<0,"minus ","")&SUBSTITUTE(TRIM(SUBSTITUTE(SUBSTITUTE(SUBSTITUTE(SUBSTITUTE(SUBSTITUTE(SUBSTITUTE(SUBSTITUTE(SUBSTITUTE(SUBSTITUTE(SUBSTITUTE(SUBSTITUTE(SUBSTITUTE(SUBSTITUTE(SUBSTITUTE(SUBSTITUTE(SUBSTITUTE(SUBSTITUTE(SUBSTITUTE(SUBSTITUTE(SUBSTITUTE(SUBSTITUTE(SUBSTITUTE(SUBSTITUTE(SUBSTITUTE(IF(--MID(TEXT(ABS(E64),"000000000000000"),1,3)=0,"",MID(TEXT(ABS(E64),"000000000000000"),1,1)&" ratus "&MID(TEXT(ABS(E64),"000000000000000"),2,1)&" puluh "&MID(TEXT(ABS(E64),"000000000000000"),3,1)&" trilyun ")&IF(--MID(TEXT(ABS(E64),"000000000000000"),4,3)=0,"",MID(TEXT(ABS(E64),"000000000000000"),4,1)&" ratus "&MID(TEXT(ABS(E64),"000000000000000"),5,1)&" puluh "&MID(TEXT(ABS(E64),"000000000000000"),6,1)&" milyar ")&IF(--MID(TEXT(ABS(E64),"000000000000000"),7,3)=0,"",MID(TEXT(ABS(E64),"000000000000000"),7,1)&" ratus "&MID(TEXT(ABS(E64),"000000000000000"),8,1)&" puluh "&MID(TEXT(ABS(E64),"000000000000000"),9,1)&" juta ")&IF(--MID(TEXT(ABS(E64),"000000000000000"),10,3)=0,"",IF(--MID(TEXT(ABS(E64),"000000000000000"),10,3)=1,"*",MID(TEXT(ABS(E64),"000000000000000"),10,1)&" ratus "&MID(TEXT(ABS(E64),"000000000000000"),11,1)&" puluh ")&MID(TEXT(ABS(E64),"000000000000000"),12,1)&" ribu ")&IF(--MID(TEXT(ABS(E64),"000000000000000"),13,3)=0,"",MID(TEXT(ABS(E64),"000000000000000"),13,1)&" ratus "&MID(TEXT(ABS(E64),"000000000000000"),14,1)&" puluh "&MID(TEXT(ABS(E64),"000000000000000"),15,1)),1,"satu"),2,"dua"),3,"tiga"),4,"empat"),5,"lima"),6,"enam"),7,"tujuh"),8,"delapan"),9,"sembilan"),"0 ratus",""),"0 puluh",""),"satu puluh 0","sepuluh"),"satu puluh satu","sebelas"),"satu puluh dua","duabelas"),"satu puluh tiga","tigabelas"),"satu puluh empat","empatbelas"),"satu puluh lima","limabelas"),"satu puluh enam","enambelas"),"satu puluh tujuh","tujuhbelas"),"satu puluh delapan","delapanbelas"),"satu puluh sembilan","sembilanbelas"),"satu ratus","seratus"),"*satu ribu","seribu"),0,""))," "," "))&" Rupiah") -> Empat Puluh Dua Juta Lima Ratus Ribu Rupiah
A68: Pembebanan Pada Kode Rekening
A69: NO | B69: Kode | C69: Uraian | G69: Anggaran | H69: Akumulasi Pencairan dana Bulan Januari s/d Desember | J69: Pencairan Saat ini | K69: Sisa Anggaran
...
