Workbook

Sheet JANUARI
A8: NOTA PENCAIRAN DANA (NPD)
A9: Nomor : 91/DIV-KEU/PPB/I/2026
A10: BENDAHARA PENGELUARAN
A11: PERUMDA PASAR BANJARMASIN
A12: Supaya Mencairkan Dana
A14: 1. Sub Kegiatan | E14: : | F14: Beban Operasional dan Bisnis
A15: 2. Nomor | E15: : | F15: 2.1.3
A16: 3. Tahun Anggaran | E16: : | F16: 2026
A17: 4. Jumlah Yang Diminta | E17: : | F17: =J30 -> 460000
E18: : | F18: =PROPER(IF(F17=0,"nol",IF(F17<0,"minus ","")&SUBSTITUTE(TRIM(SUBSTITUTE(SUBSTITUTE(SUBSTITUTE(SUBSTITUTE(SUBSTITUTE(SUBSTITUTE(SUBSTITUTE(SUBSTITUTE(SUBSTITUTE(SUBSTITUTE(SUBSTITUTE(SUBSTITUTE(SUBSTITUTE(SUBSTITUTE(SUBSTITUTE(SUBSTITUTE(SUBSTITUTE(SUBSTITUTE(SUBSTITUTE(SUBSTITUTE(SUBSTITUTE(SUBSTITUTE(SUBSTITUTE(SUBSTITUTE(IF(--MID(TEXT(ABS(F17),"000000000000000"),1,3)=0,"",MID(TEXT(ABS(F17),"000000000000000"),1,1)&" ratus "&MID(TEXT(ABS(F17),"000000000000000"),2,1)&" puluh "&MID(TEXT(ABS(F17),"000000000000000"),3,1)&" trilyun ")&IF(--MID(TEXT(ABS(F17),"000000000000000"),4,3)=0,"",MID(TEXT(ABS(F17),"000000000000000"),4,1)&" ratus "&MID(TEXT(ABS(F17),"000000000000000"),5,1)&" puluh "&MID(TEXT(ABS(F17),"000000000000000"),6,1)&" milyar ")&IF(--MID(TEXT(ABS(F17),"000000000000000"),7,3)=0,"",MID(TEXT(ABS(F17),"000000000000000"),7,1)&" ratus "&MID(TEXT(ABS(F17),"000000000000000"),8,1)&" puluh "&MID(TEXT(ABS(F17),"000000000000000"),9,1)&" juta ")&IF(--MID(TEXT(ABS(F17),"000000000000000"),10,3)=0,"",IF(--MID(TEXT(ABS(F17),"000000000000000"),10,3)=1,"*",MID(TEXT(ABS(F17),"000000000000000"),10,1)&" ratus "&MID(TEXT(ABS(F17),"000000000000000"),11,1)&" puluh ")&MID(TEXT(ABS(F17),"000000000000000"),12,1)&" ribu ")&IF(--MID(TEXT(ABS(F17),"000000000000000"),13,3)=0,"",MID(TEXT(ABS(F17),"000000000000000"),13,1)&" ratus "&MID(TEXT(ABS(F17),"000000000000000"),14,1)&" puluh "&MID(TEXT(ABS(F17),"000000000000000"),15,1)),1,"satu"),2,"dua"),3,"tiga"),4,"empat"),5,"lima"),6,"enam"),7,"tujuh"),8,"delapan"),9,"sembilan"),"0 ratus",""),"0 puluh",""),"satu puluh 0","sepuluh"),"satu puluh satu","sebelas"),"satu puluh dua","duabelas"),"satu puluh tiga","tigabelas"),"satu puluh empat","empatbelas"),"satu puluh lima","limabelas"),"satu puluh enam","enambelas"),"satu puluh tujuh","tujuhbelas"),"satu puluh delapan","delapanbelas"),"satu puluh sembilan","sembilanbelas"),"satu ratus","seratus"),"*satu ribu","seribu"),0,""))," "," "))&" Rupiah") -> Empat Ratus Enam Puluh Ribu Rupiah
A21: Pembebanan Pada Kode Rekening
A22: NO | B22: Kode | D22: Uraian | H22: Anggaran | I22: Akumulasi Pencairan dana Bulan Lalu | J22: Pencairan Saat ini | K22: Sisa Anggaran
A23: 1 | D23: Beban Pemeliharaan | H23: --------------- | I23: --------------- | J23: --------------- | K23: ---------------
B24: 1.1 | D24: Pemeliharaan Kendaraan Operasional | H24: --------------- | I24: --------------- | J24: --------------- | K24: ---------------
C25: 1.1.1 | D25: Pajak Mobil Operasional | H25: 25000000 | I25: 0 | J25: 0 | K25: =H25-I25-J25 -> 25000000
C26: 1.1.2 | D26: Parkir Mobil Operasional | H26: 3000000 | I26: 0 | J26: 0 | K26: =H26-I26-J26 -> 3000000
C27: 1.1.3 | D27: Pemeliharaan Mobil Truck (4) | H27: 58710000 | I27: 0 | J27: 460000 | K27: =H27-I27-J27 -> 58250000
C28: 1.1.4 | D28: Pemeliharaan Mobil Pick Up (1) | H28: 20000000 | I28: 0 | J28: 0 | K28: =H28-I28-J28 -> 20000000
C29: 1.1.5 | D29: Pemeliharaan Mobil Keliling (2) | H29: 10000000 | I29: 0 | J29: 0 | K29: =H29-I29-J29 -> 10000000
D30: JUMLAH | H30: =SUM(H23:H29) -> 116710000 | I30: =SUM(I24:I29) -> 0 | J30: =SUM(J24:J29) -> 460000 | K30: =SUM(K24:K29) -> 116250000
A32: Jumlah Yang Diminta | E32: : | F32: =J30 -> 460000
A33: PPN | E33: :
A34: PPh Psl 21/22/23/4(2) | E34: :
A35: Jumlah Potongan | E35: : | F35: =F33+F34 -> 0
A37: Jumlah yang dibayarkan | E37: : | F37: =F32-F35 -> 460000
F38: =PROPER(IF(F37=0,"nol",IF(F37<0,"minus ","")&SUBSTITUTE(TRIM(SUBSTITUTE(SUBSTITUTE(SUBSTITUTE(SUBSTITUTE(SUBSTITUTE(SUBSTITUTE(SUBSTITUTE(SUBSTITUTE(SUBSTITUTE(SUBSTITUTE(SUBSTITUTE(SUBSTITUTE(SUBSTITUTE(SUBSTITUTE(SUBSTITUTE(SUBSTITUTE(SUBSTITUTE(SUBSTITUTE(SUBSTITUTE(SUBSTITUTE(SUBSTITUTE(SUBSTITUTE(SUBSTITUTE(SUBSTITUTE(IF(--MID(TEXT(ABS(F37),"000000000000000"),1,3)=0,"",MID(TEXT(ABS(F37),"000000000000000"),1,1)&" ratus "&MID(TEXT(ABS(F37),"000000000000000"),2,1)&" puluh "&MID(TEXT(ABS(F37),"000000000000000"),3,1)&" trilyun ")&IF(--MID(TEXT(ABS(F37),"000000000000000"),4,3)=0,"",MID(TEXT(ABS(F37),"000000000000000"),4,1)&" ratus "&MID(TEXT(ABS(F37),"000000000000000"),5,1)&" puluh "&MID(TEXT(ABS(F37),"000000000000000"),6,1)&" milyar ")&IF(--MID(TEXT(ABS(F37),"000000000000000"),7,3)=0,"",MID(TEXT(ABS(F37),"000000000000000"),7,1)&" ratus "&MID(TEXT(ABS(F37),"000000000000000"),8,1)&" puluh "&MID(TEXT(ABS(F37),"000000000000000"),9,1)&" juta ")&IF(--MID(TEXT(ABS(F37),"000000000000000"),10,3)=0,"",IF(--MID(TEXT(ABS(F37),"000000000000000"),10,3)=1,"*",MID(TEXT(ABS(F37),"000000000000000"),10,1)&" ratus "&MID(TEXT(ABS(F37),"000000000000000"),11,1)&" puluh ")&MID(TEXT(ABS(F37),"000000000000000"),12,1)&" ribu ")&IF(--MID(TEXT(ABS(F37),"000000000000000"),13,3)=0,"",MID(TEXT(ABS(F37),"000000000000000"),13,1)&" ratus "&MID(TEXT(ABS(F37),"000000000000000"),14,1)&" puluh "&MID(TEXT(ABS(F37),"000000000000000"),15,1)),1,"satu"),2,"dua"),3,"tiga"),4,"empat"),5,"lima"),6,"enam"),7,"tujuh"),8,"delapan"),9,"sembilan"),"0 ratus",""),"0 puluh",""),"satu puluh 0","sepuluh"),"satu puluh satu","sebelas"),"satu puluh dua","duabelas"),"satu puluh tiga","tigabelas"),"satu puluh empat","empatbelas"),"satu puluh lima","limabelas"),"satu puluh enam","enambelas"),"satu puluh tujuh","tujuhbelas"),"satu puluh delapan","delapanbelas"),"satu puluh sembilan","sembilanbelas"),"satu ratus","seratus"),"*satu ribu","seribu"),0,""))," "," "))&" Rupiah") -> Empat Ratus Enam Puluh Ribu Rupiah
J41: Banjarmasin, 31 Januari 2026
A42: MENGETAHUI | J42: YANG MEMBUAT
A47: IRNA WAHYUNI N. | J47: M. ZULKIFLI
A56: NOTA PENCAIRAN DANA (NPD)
A57: Nomor : 92/DIV-KEU/PPB/I/2026
A58: BENDAHARA PENGELUARAN
A59: PERUMDA PASAR BANJARMASIN
A60: Supaya Mencairkan Dana
A62: 1. Sub Kegiatan | E62: : | F62: Beban Operasional dan Bisnis
A63: 2. Nomor | E63: : | F63: 2.1.3
A64: 3. Tahun Anggaran | E64: : | F64: 2026
A65: 4. Jumlah Yang Diminta | E65: : | F65: =J78 -> 80000
E66: : | F66: =PROPER(IF(F65=0,"nol",IF(F65<0,"minus ","")&SUBSTITUTE(TRIM(SUBSTITUTE(SUBSTITUTE(SUBSTITUTE(SUBSTITUTE(SUBSTITUTE(SUBSTITUTE(SUBSTITUTE(SUBSTITUTE(SUBSTITUTE(SUBSTITUTE(SUBSTITUTE(SUBSTITUTE(SUBSTITUTE(SUBSTITUTE(SUBSTITUTE(SUBSTITUTE(SUBSTITUTE(SUBSTITUTE(SUBSTITUTE(SUBSTITUTE(SUBSTITUTE(SUBSTITUTE(SUBSTITUTE(SUBSTITUTE(IF(--MID(TEXT(ABS(F65),"000000000000000"),1,3)=0,"",MID(TEXT(ABS(F65),"000000000000000"),1,1)&" ratus "&MID(TEXT(ABS(F65),"000000000000000"),2,1)&" puluh "&MID(TEXT(ABS(F65),"000000000000000"),3,1)&" trilyun ")&IF(--MID(TEXT(ABS(F65),"000000000000000"),4,3)=0,"",MID(TEXT(ABS(F65),"000000000000000"),4,1)&" ratus "&MID(TEXT(ABS(F65),"000000000000000"),5,1)&" puluh "&MID(TEXT(ABS(F65),"000000000000000"),6,1)&" milyar ")&IF(--MID(TEXT(ABS(F65),"000000000000000"),7,3)=0,"",MID(TEXT(ABS(F65),"000000000000000"),7,1)&" ratus "&MID(TEXT(ABS(F65),"000000000000000"),8,1)&" puluh "&MID(TEXT(ABS(F65),"000000000000000"),9,1)&" juta ")&IF(--MID(TEXT(ABS(F65),"000000000000000"),10,3)=0,"",IF(--MID(TEXT(ABS(F65),"000000000000000"),10,3)=1,"*",MID(TEXT(ABS(F65),"000000000000000"),10,1)&" ratus "&MID(TEXT(ABS(F65),"000000000000000"),11,1)&" puluh ")&MID(TEXT(ABS(F65),"000000000000000"),12,1)&" ribu ")&IF(--MID(TEXT(ABS(F65),"000000000000000"),13,3)=0,"",MID(TEXT(ABS(F65),"000000000000000"),13,1)&" ratus "&MID(TEXT(ABS(F65),"000000000000000"),14,1)&" puluh "&MID(TEXT(ABS(F65),"000000000000000"),15,1)),1,"satu"),2,"dua"),3,"tiga"),4,"empat"),5,"lima"),6,"enam"),7,"tujuh"),8,"delapan"),9,"sembilan"),"0 ratus",""),"0 puluh",""),"satu puluh 0","sepuluh"),"satu puluh satu","sebelas"),"satu puluh dua","duabelas"),"satu puluh tiga","tigabelas"),"satu puluh empat","empatbelas"),"satu puluh lima","limabelas"),"satu puluh enam","enambelas"),"satu puluh tujuh","tujuhbelas"),"satu puluh delapan","delapanbelas"),"satu puluh sembilan","sembilanbelas"),"satu ratus","seratus"),"*satu ribu","seribu"),0,""))," "," "))&" Rupiah") -> Delapan Puluh Ribu Rupiah
A69: Pembebanan Pada Kode Rekening
...

Sheet FEBRUARI
A8: NOTA PENCAIRAN DANA (NPD)
A9: Nomor : 060/DIV-KEU/PPB/II/2026
A10: BENDAHARA PENGELUARAN
A11: PERUMDA PASAR BANJARMASIN
A12: Supaya Mencairkan Dana
A14: 1. Sub Kegiatan | E14: : | F14: Beban Operasional dan Bisnis
A15: 2. Nomor | E15: : | F15: 2.1.3
A16: 3. Tahun Anggaran | E16: : | F16: 2026
A17: 4. Jumlah Yang Diminta | E17: : | F17: =J30 -> 3016980
E18: : | F18: =PROPER(IF(F17=0,"nol",IF(F17<0,"minus ","")&SUBSTITUTE(TRIM(SUBSTITUTE(SUBSTITUTE(SUBSTITUTE(SUBSTITUTE(SUBSTITUTE(SUBSTITUTE(SUBSTITUTE(SUBSTITUTE(SUBSTITUTE(SUBSTITUTE(SUBSTITUTE(SUBSTITUTE(SUBSTITUTE(SUBSTITUTE(SUBSTITUTE(SUBSTITUTE(SUBSTITUTE(SUBSTITUTE(SUBSTITUTE(SUBSTITUTE(SUBSTITUTE(SUBSTITUTE(SUBSTITUTE(SUBSTITUTE(IF(--MID(TEXT(ABS(F17),"000000000000000"),1,3)=0,"",MID(TEXT(ABS(F17),"000000000000000"),1,1)&" ratus "&MID(TEXT(ABS(F17),"000000000000000"),2,1)&" puluh "&MID(TEXT(ABS(F17),"000000000000000"),3,1)&" trilyun ")&IF(--MID(TEXT(ABS(F17),"000000000000000"),4,3)=0,"",MID(TEXT(ABS(F17),"000000000000000"),4,1)&" ratus "&MID(TEXT(ABS(F17),"000000000000000"),5,1)&" puluh "&MID(TEXT(ABS(F17),"000000000000000"),6,1)&" milyar ")&IF(--MID(TEXT(ABS(F17),"000000000000000"),7,3)=0,"",MID(TEXT(ABS(F17),"000000000000000"),7,1)&" ratus "&MID(TEXT(ABS(F17),"000000000000000"),8,1)&" puluh "&MID(TEXT(ABS(F17),"000000000000000"),9,1)&" juta ")&IF(--MID(TEXT(ABS(F17),"000000000000000"),10,3)=0,"",IF(--MID(TEXT(ABS(F17),"000000000000000"),10,3)=1,"*",MID(TEXT(ABS(F17),"000000000000000"),10,1)&" ratus "&MID(TEXT(ABS(F17),"000000000000000"),11,1)&" puluh ")&MID(TEXT(ABS(F17),"000000000000000"),12,1)&" ribu ")&IF(--MID(TEXT(ABS(F17),"000000000000000"),13,3)=0,"",MID(TEXT(ABS(F17),"000000000000000"),13,1)&" ratus "&MID(TEXT(ABS(F17),"000000000000000"),14,1)&" puluh "&MID(TEXT(ABS(F17),"000000000000000"),15,1)),1,"satu"),2,"dua"),3,"tiga"),4,"empat"),5,"lima"),6,"enam"),7,"tujuh"),8,"delapan"),9,"sembilan"),"0 ratus",""),"0 puluh",""),"satu puluh 0","sepuluh"),"satu puluh satu","sebelas"),"satu puluh dua","duabelas"),"satu puluh tiga","tigabelas"),"satu puluh empat","empatbelas"),"satu puluh lima","limabelas"),"satu puluh enam","enambelas"),"satu puluh tujuh","tujuhbelas"),"satu puluh delapan","delapanbelas"),"satu puluh sembilan","sembilanbelas"),"satu ratus","seratus"),"*satu ribu","seribu"),0,""))," "," "))&" Rupiah") -> Tiga Juta Enambelas Ribu Sembilan Ratus Delapan Puluh Rupiah
A21: Pembebanan Pada Kode Rekening
A22: NO | B22: Kode | D22: Uraian | H22: Anggaran | I22: Akumulasi Pencairan dana Bulan Lalu | J22: Pencairan Saat ini | K22: Sisa Anggaran
A23: 1 | D23: Beban Pemeliharaan | H23: --------------- | I23: --------------- | J23: --------------- | K23: ---------------
B24: 1.1 | D24: Pemeliharaan Kendaraan Operasional | H24: --------------- | I24: --------------- | J24: --------------- | K24: ---------------
C25: 1.1.1 | D25: Pajak Mobil Operasional | H25: 25000000 | I25: =JANUARI!I121+JANUARI!J121 -> 0 | J25: 0 | K25: =H25-I25-J25 -> 25000000
C26: 1.1.2 | D26: Parkir Mobil Operasional | H26: 3000000 | I26: =JANUARI!I122+JANUARI!J122 -> 220000 | J26: 0 | K26: =H26-I26-J26 -> 2780000
C27: 1.1.3 | D27: Pemeliharaan Mobil Truck (4) | H27: 58710000 | I27: =JANUARI!I123+JANUARI!J123 -> 460000 | J27: 3016980 | K27: =H27-I27-J27 -> 55233020
C28: 1.1.4 | D28: Pemeliharaan Mobil Pick Up (1) | H28: 20000000 | I28: =JANUARI!I124+JANUARI!J124 -> 0 | J28: 0 | K28: =H28-I28-J28 -> 20000000
C29: 1.1.5 | D29: Pemeliharaan Mobil Keliling (2) | H29: 10000000 | I29: =JANUARI!I125+JANUARI!J125 -> 80000 | J29: 0 | K29: =H29-I29-J29 -> 9920000
D30: JUMLAH | H30: =SUM(H23:H29) -> 116710000 | I30: =SUM(I24:I29) -> 760000 | J30: =SUM(J24:J29) -> 3016980 | K30: =SUM(K24:K29) -> 112933020
A32: Jumlah Yang Diminta | E32: : | F32: =J30 -> 3016980
A33: PPN | E33: :
A34: PPh Psl 21/22/23/4(2) | E34: :
A35: Jumlah Potongan | E35: : | F35: =F33+F34 -> 0
A37: Jumlah yang dibayarkan | E37: : | F37: =F32-F35 -> 3016980
F38: =PROPER(IF(F37=0,"nol",IF(F37<0,"minus ","")&SUBSTITUTE(TRIM(SUBSTITUTE(SUBSTITUTE(SUBSTITUTE(SUBSTITUTE(SUBSTITUTE(SUBSTITUTE(SUBSTITUTE(SUBSTITUTE(SUBSTITUTE(SUBSTITUTE(SUBSTITUTE(SUBSTITUTE(SUBSTITUTE(SUBSTITUTE(SUBSTITUTE(SUBSTITUTE(SUBSTITUTE(SUBSTITUTE(SUBSTITUTE(SUBSTITUTE(SUBSTITUTE(SUBSTITUTE(SUBSTITUTE(SUBSTITUTE(IF(--MID(TEXT(ABS(F37),"000000000000000"),1,3)=0,"",MID(TEXT(ABS(F37),"000000000000000"),1,1)&" ratus "&MID(TEXT(ABS(F37),"000000000000000"),2,1)&" puluh "&MID(TEXT(ABS(F37),"000000000000000"),3,1)&" trilyun ")&IF(--MID(TEXT(ABS(F37),"000000000000000"),4,3)=0,"",MID(TEXT(ABS(F37),"000000000000000"),4,1)&" ratus "&MID(TEXT(ABS(F37),"000000000000000"),5,1)&" puluh "&MID(TEXT(ABS(F37),"000000000000000"),6,1)&" milyar ")&IF(--MID(TEXT(ABS(F37),"000000000000000"),7,3)=0,"",MID(TEXT(ABS(F37),"000000000000000"),7,1)&" ratus "&MID(TEXT(ABS(F37),"000000000000000"),8,1)&" puluh "&MID(TEXT(ABS(F37),"000000000000000"),9,1)&" juta ")&IF(--MID(TEXT(ABS(F37),"000000000000000"),10,3)=0,"",IF(--MID(TEXT(ABS(F37),"000000000000000"),10,3)=1,"*",MID(TEXT(ABS(F37),"000000000000000"),10,1)&" ratus "&MID(TEXT(ABS(F37),"000000000000000"),11,1)&" puluh ")&MID(TEXT(ABS(F37),"000000000000000"),12,1)&" ribu ")&IF(--MID(TEXT(ABS(F37),"000000000000000"),13,3)=0,"",MID(TEXT(ABS(F37),"000000000000000"),13,1)&" ratus "&MID(TEXT(ABS(F37),"000000000000000"),14,1)&" puluh "&MID(TEXT(ABS(F37),"000000000000000"),15,1)),1,"satu"),2,"dua"),3,"tiga"),4,"empat"),5,"lima"),6,"enam"),7,"tujuh"),8,"delapan"),9,"sembilan"),"0 ratus",""),"0 puluh",""),"satu puluh 0","sepuluh"),"satu puluh satu","sebelas"),"satu puluh dua","duabelas"),"satu puluh tiga","tigabelas"),"satu puluh empat","empatbelas"),"satu puluh lima","limabelas"),"satu puluh enam","enambelas"),"satu puluh tujuh","tujuhbelas"),"satu puluh delapan","delapanbelas"),"satu puluh sembilan","sembilanbelas"),"satu ratus","seratus"),"*satu ribu","seribu"),0,""))," "," "))&" Rupiah") -> Tiga Juta Enambelas Ribu Sembilan Ratus Delapan Puluh Rupiah
J41: Banjarmasin, 11 Februari 2026
A42: MENGETAHUI | J42: YANG MEMBUAT
A47: IRNA WAHYUNI N. | J47: M. ZULKIFLI
A56: NOTA PENCAIRAN DANA (NPD)
A57: Nomor : 092/DIV-KEU/PPB/II/2026
A58: BENDAHARA PENGELUARAN
A59: PERUMDA PASAR BANJARMASIN
A60: Supaya Mencairkan Dana
A62: 1. Sub Kegiatan | E62: : | F62: Beban Operasional dan Bisnis
A63: 2. Nomor | E63: : | F63: 2.1.3
A64: 3. Tahun Anggaran | E64: : | F64: 2026
A65: 4. Jumlah Yang Diminta | E65: : | F65: =J78 -> 25115000
E66: : | F66: =PROPER(IF(F65=0,"nol",IF(F65<0,"minus ","")&SUBSTITUTE(TRIM(SUBSTITUTE(SUBSTITUTE(SUBSTITUTE(SUBSTITUTE(SUBSTITUTE(SUBSTITUTE(SUBSTITUTE(SUBSTITUTE(SUBSTITUTE(SUBSTITUTE(SUBSTITUTE(SUBSTITUTE(SUBSTITUTE(SUBSTITUTE(SUBSTITUTE(SUBSTITUTE(SUBSTITUTE(SUBSTITUTE(SUBSTITUTE(SUBSTITUTE(SUBSTITUTE(SUBSTITUTE(SUBSTITUTE(SUBSTITUTE(IF(--MID(TEXT(ABS(F65),"000000000000000"),1,3)=0,"",MID(TEXT(ABS(F65),"000000000000000"),1,1)&" ratus "&MID(TEXT(ABS(F65),"000000000000000"),2,1)&" puluh "&MID(TEXT(ABS(F65),"000000000000000"),3,1)&" trilyun ")&IF(--MID(TEXT(ABS(F65),"000000000000000"),4,3)=0,"",MID(TEXT(ABS(F65),"000000000000000"),4,1)&" ratus "&MID(TEXT(ABS(F65),"000000000000000"),5,1)&" puluh "&MID(TEXT(ABS(F65),"000000000000000"),6,1)&" milyar ")&IF(--MID(TEXT(ABS(F65),"000000000000000"),7,3)=0,"",MID(TEXT(ABS(F65),"000000000000000"),7,1)&" ratus "&MID(TEXT(ABS(F65),"000000000000000"),8,1)&" puluh "&MID(TEXT(ABS(F65),"000000000000000"),9,1)&" juta ")&IF(--MID(TEXT(ABS(F65),"000000000000000"),10,3)=0,"",IF(--MID(TEXT(ABS(F65),"000000000000000"),10,3)=1,"*",MID(TEXT(ABS(F65),"000000000000000"),10,1)&" ratus "&MID(TEXT(ABS(F65),"000000000000000"),11,1)&" puluh ")&MID(TEXT(ABS(F65),"000000000000000"),12,1)&" ribu ")&IF(--MID(TEXT(ABS(F65),"000000000000000"),13,3)=0,"",MID(TEXT(ABS(F65),"000000000000000"),13,1)&" ratus "&MID(TEXT(ABS(F65),"000000000000000"),14,1)&" puluh "&MID(TEXT(ABS(F65),"000000000000000"),15,1)),1,"satu"),2,"dua"),3,"tiga"),4,"empat"),5,"lima"),6,"enam"),7,"tujuh"),8,"delapan"),9,"sembilan"),"0 ratus",""),"0 puluh",""),"satu puluh 0","sepuluh"),"satu puluh satu","sebelas"),"satu puluh dua","duabelas"),"satu puluh tiga","tigabelas"),"satu puluh empat","empatbelas"),"satu puluh lima","limabelas"),"satu puluh enam","enambelas"),"satu puluh tujuh","tujuhbelas"),"satu puluh delapan","delapanbelas"),"satu puluh sembilan","sembilanbelas"),"satu ratus","seratus"),"*satu ribu","seribu"),0,""))," "," "))&" Rupiah") -> Dua Puluh Lima Juta Seratus Limabelas Ribu Rupiah
A69: Pembebanan Pada Kode Rekening
...

Sheet MARET
A8: NOTA PENCAIRAN DANA (NPD)
A9: Nomor : 028/DIV-KEU/PPB/III/2026
A10: BENDAHARA PENGELUARAN
A11: PERUMDA PASAR BANJARMASIN
A12: Supaya Mencairkan Dana
A14: 1. Sub Kegiatan | E14: : | F14: Beban Operasional dan Bisnis
A15: 2. Nomor | E15: : | F15: 2.1.3
A16: 3. Tahun Anggaran | E16: : | F16: 2026
A17: 4. Jumlah Yang Diminta | E17: : | F17: =J30 -> 80000
E18: : | F18: =PROPER(IF(F17=0,"nol",IF(F17<0,"minus ","")&SUBSTITUTE(TRIM(SUBSTITUTE(SUBSTITUTE(SUBSTITUTE(SUBSTITUTE(SUBSTITUTE(SUBSTITUTE(SUBSTITUTE(SUBSTITUTE(SUBSTITUTE(SUBSTITUTE(SUBSTITUTE(SUBSTITUTE(SUBSTITUTE(SUBSTITUTE(SUBSTITUTE(SUBSTITUTE(SUBSTITUTE(SUBSTITUTE(SUBSTITUTE(SUBSTITUTE(SUBSTITUTE(SUBSTITUTE(SUBSTITUTE(SUBSTITUTE(IF(--MID(TEXT(ABS(F17),"000000000000000"),1,3)=0,"",MID(TEXT(ABS(F17),"000000000000000"),1,1)&" ratus "&MID(TEXT(ABS(F17),"000000000000000"),2,1)&" puluh "&MID(TEXT(ABS(F17),"000000000000000"),3,1)&" trilyun ")&IF(--MID(TEXT(ABS(F17),"000000000000000"),4,3)=0,"",MID(TEXT(ABS(F17),"000000000000000"),4,1)&" ratus "&MID(TEXT(ABS(F17),"000000000000000"),5,1)&" puluh "&MID(TEXT(ABS(F17),"000000000000000"),6,1)&" milyar ")&IF(--MID(TEXT(ABS(F17),"000000000000000"),7,3)=0,"",MID(TEXT(ABS(F17),"000000000000000"),7,1)&" ratus "&MID(TEXT(ABS(F17),"000000000000000"),8,1)&" puluh "&MID(TEXT(ABS(F17),"000000000000000"),9,1)&" juta ")&IF(--MID(TEXT(ABS(F17),"000000000000000"),10,3)=0,"",IF(--MID(TEXT(ABS(F17),"000000000000000"),10,3)=1,"*",MID(TEXT(ABS(F17),"000000000000000"),10,1)&" ratus "&MID(TEXT(ABS(F17),"000000000000000"),11,1)&" puluh ")&MID(TEXT(ABS(F17),"000000000000000"),12,1)&" ribu ")&IF(--MID(TEXT(ABS(F17),"000000000000000"),13,3)=0,"",MID(TEXT(ABS(F17),"000000000000000"),13,1)&" ratus "&MID(TEXT(ABS(F17),"000000000000000"),14,1)&" puluh "&MID(TEXT(ABS(F17),"000000000000000"),15,1)),1,"satu"),2,"dua"),3,"tiga"),4,"empat"),5,"lima"),6,"enam"),7,"tujuh"),8,"delapan"),9,"sembilan"),"0 ratus",""),"0 puluh",""),"satu puluh 0","sepuluh"),"satu puluh satu","sebelas"),"satu puluh dua","duabelas"),"satu puluh tiga","tigabelas"),"satu puluh empat","empatbelas"),"satu puluh lima","limabelas"),"satu puluh enam","enambelas"),"satu puluh tujuh","tujuhbelas"),"satu puluh delapan","delapanbelas"),"satu puluh sembilan","sembilanbelas"),"satu ratus","seratus"),"*satu ribu","seribu"),0,""))," "," "))&" Rupiah") -> Delapan Puluh Ribu Rupiah
A21: Pembebanan Pada Kode Rekening
A22: NO | B22: Kode | D22: Uraian | H22: Anggaran | I22: Akumulasi Pencairan dana Bulan Lalu | J22: Pencairan Saat ini | K22: Sisa Anggaran
A23: 1 | D23: Beban Pemeliharaan | H23: --------------- | I23: --------------- | J23: --------------- | K23: ---------------
B24: 1.1 | D24: Pemeliharaan Kendaraan Operasional | H24: --------------- | I24: --------------- | J24: --------------- | K24: ---------------
C25: 1.1.1 | D25: Pajak Mobil Operasional | H25: 25000000 | I25: =FEBRUARI!I169+FEBRUARI!J169 -> 0 | J25: 0 | K25: =H25-I25-J25 -> 25000000
C26: 1.1.2 | D26: Parkir Mobil Operasional | H26: 3000000 | I26: =FEBRUARI!I170+FEBRUARI!J170 -> 400000 | J26: 0 | K26: =H26-I26-J26 -> 2600000
C27: 1.1.3 | D27: Pemeliharaan Mobil Truck (4) | H27: 58710000 | I27: =FEBRUARI!I171+FEBRUARI!J171 -> 23571980 | J27: 0 | K27: =H27-I27-J27 -> 35138020
C28: 1.1.4 | D28: Pemeliharaan Mobil Pick Up (1) | H28: 20000000 | I28: =FEBRUARI!I172+FEBRUARI!J172 -> 3150000 | J28: 0 | K28: =H28-I28-J28 -> 16850000
C29: 1.1.5 | D29: Pemeliharaan Mobil Keliling (2) | H29: 10000000 | I29: =FEBRUARI!I173+FEBRUARI!J173 -> 2405000 | J29: 80000 | K29: =H29-I29-J29 -> 7515000
D30: JUMLAH | H30: =SUM(H23:H29) -> 116710000 | I30: =SUM(I24:I29) -> 29526980 | J30: =SUM(J24:J29) -> 80000 | K30: =SUM(K24:K29) -> 87103020
A32: Jumlah Yang Diminta | E32: : | F32: =J30 -> 80000
A33: PPN | E33: :
A34: PPh Psl 21/22/23/4(2) | E34: :
A35: Jumlah Potongan | E35: : | F35: =F33+F34 -> 0
A37: Jumlah yang dibayarkan | E37: : | F37: =F32-F35 -> 80000
F38: =PROPER(IF(F37=0,"nol",IF(F37<0,"minus ","")&SUBSTITUTE(TRIM(SUBSTITUTE(SUBSTITUTE(SUBSTITUTE(SUBSTITUTE(SUBSTITUTE(SUBSTITUTE(SUBSTITUTE(SUBSTITUTE(SUBSTITUTE(SUBSTITUTE(SUBSTITUTE(SUBSTITUTE(SUBSTITUTE(SUBSTITUTE(SUBSTITUTE(SUBSTITUTE(SUBSTITUTE(SUBSTITUTE(SUBSTITUTE(SUBSTITUTE(SUBSTITUTE(SUBSTITUTE(SUBSTITUTE(SUBSTITUTE(IF(--MID(TEXT(ABS(F37),"000000000000000"),1,3)=0,"",MID(TEXT(ABS(F37),"000000000000000"),1,1)&" ratus "&MID(TEXT(ABS(F37),"000000000000000"),2,1)&" puluh "&MID(TEXT(ABS(F37),"000000000000000"),3,1)&" trilyun ")&IF(--MID(TEXT(ABS(F37),"000000000000000"),4,3)=0,"",MID(TEXT(ABS(F37),"000000000000000"),4,1)&" ratus "&MID(TEXT(ABS(F37),"000000000000000"),5,1)&" puluh "&MID(TEXT(ABS(F37),"000000000000000"),6,1)&" milyar ")&IF(--MID(TEXT(ABS(F37),"000000000000000"),7,3)=0,"",MID(TEXT(ABS(F37),"000000000000000"),7,1)&" ratus "&MID(TEXT(ABS(F37),"000000000000000"),8,1)&" puluh "&MID(TEXT(ABS(F37),"000000000000000"),9,1)&" juta ")&IF(--MID(TEXT(ABS(F37),"000000000000000"),10,3)=0,"",IF(--MID(TEXT(ABS(F37),"000000000000000"),10,3)=1,"*",MID(TEXT(ABS(F37),"000000000000000"),10,1)&" ratus "&MID(TEXT(ABS(F37),"000000000000000"),11,1)&" puluh ")&MID(TEXT(ABS(F37),"000000000000000"),12,1)&" ribu ")&IF(--MID(TEXT(ABS(F37),"000000000000000"),13,3)=0,"",MID(TEXT(ABS(F37),"000000000000000"),13,1)&" ratus "&MID(TEXT(ABS(F37),"000000000000000"),14,1)&" puluh "&MID(TEXT(ABS(F37),"000000000000000"),15,1)),1,"satu"),2,"dua"),3,"tiga"),4,"empat"),5,"lima"),6,"enam"),7,"tujuh"),8,"delapan"),9,"sembilan"),"0 ratus",""),"0 puluh",""),"satu puluh 0","sepuluh"),"satu puluh satu","sebelas"),"satu puluh dua","duabelas"),"satu puluh tiga","tigabelas"),"satu puluh empat","empatbelas"),"satu puluh lima","limabelas"),"satu puluh enam","enambelas"),"satu puluh tujuh","tujuhbelas"),"satu puluh delapan","delapanbelas"),"satu puluh sembilan","sembilanbelas"),"satu ratus","seratus"),"*satu ribu","seribu"),0,""))," "," "))&" Rupiah") -> Delapan Puluh Ribu Rupiah
J41: Banjarmasin, 12 Maret 2026
A42: MENGETAHUI | J42: YANG MEMBUAT
A47: IRNA WAHYUNI N. | J47: M. ZULKIFLI
A56: NOTA PENCAIRAN DANA (NPD)
A57: Nomor : 033/DIV-KEU/PPB/III/2026
A58: BENDAHARA PENGELUARAN
A59: PERUMDA PASAR BANJARMASIN
A60: Supaya Mencairkan Dana
A62: 1. Sub Kegiatan | E62: : | F62: Beban Operasional dan Bisnis
A63: 2. Nomor | E63: : | F63: 2.1.3
A64: 3. Tahun Anggaran | E64: : | F64: 2026
A65: 4. Jumlah Yang Diminta | E65: : | F65: =J78 -> 999000
E66: : | F66: =PROPER(IF(F65=0,"nol",IF(F65<0,"minus ","")&SUBSTITUTE(TRIM(SUBSTITUTE(SUBSTITUTE(SUBSTITUTE(SUBSTITUTE(SUBSTITUTE(SUBSTITUTE(SUBSTITUTE(SUBSTITUTE(SUBSTITUTE(SUBSTITUTE(SUBSTITUTE(SUBSTITUTE(SUBSTITUTE(SUBSTITUTE(SUBSTITUTE(SUBSTITUTE(SUBSTITUTE(SUBSTITUTE(SUBSTITUTE(SUBSTITUTE(SUBSTITUTE(SUBSTITUTE(SUBSTITUTE(SUBSTITUTE(IF(--MID(TEXT(ABS(F65),"000000000000000"),1,3)=0,"",MID(TEXT(ABS(F65),"000000000000000"),1,1)&" ratus "&MID(TEXT(ABS(F65),"000000000000000"),2,1)&" puluh "&MID(TEXT(ABS(F65),"000000000000000"),3,1)&" trilyun ")&IF(--MID(TEXT(ABS(F65),"000000000000000"),4,3)=0,"",MID(TEXT(ABS(F65),"000000000000000"),4,1)&" ratus "&MID(TEXT(ABS(F65),"000000000000000"),5,1)&" puluh "&MID(TEXT(ABS(F65),"000000000000000"),6,1)&" milyar ")&IF(--MID(TEXT(ABS(F65),"000000000000000"),7,3)=0,"",MID(TEXT(ABS(F65),"000000000000000"),7,1)&" ratus "&MID(TEXT(ABS(F65),"000000000000000"),8,1)&" puluh "&MID(TEXT(ABS(F65),"000000000000000"),9,1)&" juta ")&IF(--MID(TEXT(ABS(F65),"000000000000000"),10,3)=0,"",IF(--MID(TEXT(ABS(F65),"000000000000000"),10,3)=1,"*",MID(TEXT(ABS(F65),"000000000000000"),10,1)&" ratus "&MID(TEXT(ABS(F65),"000000000000000"),11,1)&" puluh ")&MID(TEXT(ABS(F65),"000000000000000"),12,1)&" ribu ")&IF(--MID(TEXT(ABS(F65),"000000000000000"),13,3)=0,"",MID(TEXT(ABS(F65),"000000000000000"),13,1)&" ratus "&MID(TEXT(ABS(F65),"000000000000000"),14,1)&" puluh "&MID(TEXT(ABS(F65),"000000000000000"),15,1)),1,"satu"),2,"dua"),3,"tiga"),4,"empat"),5,"lima"),6,"enam"),7,"tujuh"),8,"delapan"),9,"sembilan"),"0 ratus",""),"0 puluh",""),"satu puluh 0","sepuluh"),"satu puluh satu","sebelas"),"satu puluh dua","duabelas"),"satu puluh tiga","tigabelas"),"satu puluh empat","empatbelas"),"satu puluh lima","limabelas"),"satu puluh enam","enambelas"),"satu puluh tujuh","tujuhbelas"),"satu puluh delapan","delapanbelas"),"satu puluh sembilan","sembilanbelas"),"satu ratus","seratus"),"*satu ribu","seribu"),0,""))," "," "))&" Rupiah") -> Sembilan Ratus Sembilan Puluh Sembilan Ribu Rupiah
A69: Pembebanan Pada Kode Rekening
...
