Workbook

Sheet JANUARI
A8: NOTA PENCAIRAN DANA (NPD)
A9: Nomor : 10/DIV-KEU/PPB/I/2026
A10: BENDAHARA PENGELUARAN
A11: PERUMDA PASAR BANJARMASIN
A12: Supaya Mencairkan Dana
A14: 1. Sub Kegiatan | D14: : | E14: Beban Operasional dan Bisnis
A15: 2. Nomor | D15: : | E15: 2.1.3
A16: 3. Tahun Anggaran | D16: : | E16: 2026
A17: 4. Jumlah Yang Diminta | D17: : | E17: =I30 -> 850000
D18: : | E18: =PROPER(IF(E17=0,"nol",IF(E17<0,"minus ","")&SUBSTITUTE(TRIM(SUBSTITUTE(SUBSTITUTE(SUBSTITUTE(SUBSTITUTE(SUBSTITUTE(SUBSTITUTE(SUBSTITUTE(SUBSTITUTE(SUBSTITUTE(SUBSTITUTE(SUBSTITUTE(SUBSTITUTE(SUBSTITUTE(SUBSTITUTE(SUBSTITUTE(SUBSTITUTE(SUBSTITUTE(SUBSTITUTE(SUBSTITUTE(SUBSTITUTE(SUBSTITUTE(SUBSTITUTE(SUBSTITUTE(SUBSTITUTE(IF(--MID(TEXT(ABS(E17),"000000000000000"),1,3)=0,"",MID(TEXT(ABS(E17),"000000000000000"),1,1)&" ratus "&MID(TEXT(ABS(E17),"000000000000000"),2,1)&" puluh "&MID(TEXT(ABS(E17),"000000000000000"),3,1)&" trilyun ")&IF(--MID(TEXT(ABS(E17),"000000000000000"),4,3)=0,"",MID(TEXT(ABS(E17),"000000000000000"),4,1)&" ratus "&MID(TEXT(ABS(E17),"000000000000000"),5,1)&" puluh "&MID(TEXT(ABS(E17),"000000000000000"),6,1)&" milyar ")&IF(--MID(TEXT(ABS(E17),"000000000000000"),7,3)=0,"",MID(TEXT(ABS(E17),"000000000000000"),7,1)&" ratus "&MID(TEXT(ABS(E17),"000000000000000"),8,1)&" puluh "&MID(TEXT(ABS(E17),"000000000000000"),9,1)&" juta ")&IF(--MID(TEXT(ABS(E17),"000000000000000"),10,3)=0,"",IF(--MID(TEXT(ABS(E17),"000000000000000"),10,3)=1,"*",MID(TEXT(ABS(E17),"000000000000000"),10,1)&" ratus "&MID(TEXT(ABS(E17),"000000000000000"),11,1)&" puluh ")&MID(TEXT(ABS(E17),"000000000000000"),12,1)&" ribu ")&IF(--MID(TEXT(ABS(E17),"000000000000000"),13,3)=0,"",MID(TEXT(ABS(E17),"000000000000000"),13,1)&" ratus "&MID(TEXT(ABS(E17),"000000000000000"),14,1)&" puluh "&MID(TEXT(ABS(E17),"000000000000000"),15,1)),1,"satu"),2,"dua"),3,"tiga"),4,"empat"),5,"lima"),6,"enam"),7,"tujuh"),8,"delapan"),9,"sembilan"),"0 ratus",""),"0 puluh",""),"satu puluh 0","sepuluh"),"satu puluh satu","sebelas"),"satu puluh dua","duabelas"),"satu puluh tiga","tigabelas"),"satu puluh empat","empatbelas"),"satu puluh lima","limabelas"),"satu puluh enam","enambelas"),"satu puluh tujuh","tujuhbelas"),"satu puluh delapan","delapanbelas"),"satu puluh sembilan","sembilanbelas"),"satu ratus","seratus"),"*satu ribu","seribu"),0,""))," "," "))&" Rupiah") -> Delapan Ratus Lima Puluh Ribu Rupiah
A21: Pembebanan Pada Kode Rekening
A22: NO | C22: Uraian | G22: Anggaran | H22: Akumulasi Pencairan dana Bulan Lalu | I22: Pencairan Saat ini | J22: Sisa Anggaran
A23: 1 | C23: Kelengkapan Pegawai | G23: --------------- | H23: --------------- | I23: --------------- | J23: ---------------
B24: 1.1 | C24: Atribut Petugas Penagihan (Rompi + Tas) | G24: 10000000 | H24: 0 | I24: 0 | J24: =G24-H24-I24 -> 10000000
B25: 1.2 | C25: Baju Petugas Kebersihan | G25: 28600000 | H25: 0 | I25: 0 | J25: =G25-H25-I25 -> 28600000
B26: 1.3 | C26: Atribut Petugas Kebersihan (Sepatu Booth + Jas Hujan + Rompi Scotlight) | G26: 20000000 | H26: 0 | I26: 850000 | J26: =G26-H26-I26 -> 19150000
B27: 1.4 | C27: Cetak ID Card + Pin Perumda | G27: 3000000 | H27: 0 | I27: 0 | J27: =G27-H27-I27 -> 3000000
B28: 1.5 | C28: Atribut Petugas Parkir (Baju + Topi) | G28: 15000000 | H28: 0 | I28: 0 | J28: =G28-H28-I28 -> 15000000
B29: 1.6 | C29: Atribut Petugas Keamanan (29) | G29: 28175000 | H29: 0 | I29: 0 | J29: =G29-H29-I29 -> 28175000
C30: JUMLAH | G30: =SUM(G23:G29) -> 104775000 | H30: =SUM(H23:H27) -> 0 | I30: =SUM(I23:I27) -> 850000 | J30: =SUM(J23:K29) -> 103925000
A32: Jumlah Yang Diminta | D32: : | E32: =I30 -> 850000
A33: PPN | D33: :
A34: PPh Psl 21/22/23/4(2) | D34: :
A35: Jumlah Potongan | D35: : | E35: =E33+E34 -> 0
A37: Jumlah yang dibayarkan | D37: : | E37: =E32-E35 -> 850000
E38: =PROPER(IF(E37=0,"nol",IF(E37<0,"minus ","")&SUBSTITUTE(TRIM(SUBSTITUTE(SUBSTITUTE(SUBSTITUTE(SUBSTITUTE(SUBSTITUTE(SUBSTITUTE(SUBSTITUTE(SUBSTITUTE(SUBSTITUTE(SUBSTITUTE(SUBSTITUTE(SUBSTITUTE(SUBSTITUTE(SUBSTITUTE(SUBSTITUTE(SUBSTITUTE(SUBSTITUTE(SUBSTITUTE(SUBSTITUTE(SUBSTITUTE(SUBSTITUTE(SUBSTITUTE(SUBSTITUTE(SUBSTITUTE(IF(--MID(TEXT(ABS(E37),"000000000000000"),1,3)=0,"",MID(TEXT(ABS(E37),"000000000000000"),1,1)&" ratus "&MID(TEXT(ABS(E37),"000000000000000"),2,1)&" puluh "&MID(TEXT(ABS(E37),"000000000000000"),3,1)&" trilyun ")&IF(--MID(TEXT(ABS(E37),"000000000000000"),4,3)=0,"",MID(TEXT(ABS(E37),"000000000000000"),4,1)&" ratus "&MID(TEXT(ABS(E37),"000000000000000"),5,1)&" puluh "&MID(TEXT(ABS(E37),"000000000000000"),6,1)&" milyar ")&IF(--MID(TEXT(ABS(E37),"000000000000000"),7,3)=0,"",MID(TEXT(ABS(E37),"000000000000000"),7,1)&" ratus "&MID(TEXT(ABS(E37),"000000000000000"),8,1)&" puluh "&MID(TEXT(ABS(E37),"000000000000000"),9,1)&" juta ")&IF(--MID(TEXT(ABS(E37),"000000000000000"),10,3)=0,"",IF(--MID(TEXT(ABS(E37),"000000000000000"),10,3)=1,"*",MID(TEXT(ABS(E37),"000000000000000"),10,1)&" ratus "&MID(TEXT(ABS(E37),"000000000000000"),11,1)&" puluh ")&MID(TEXT(ABS(E37),"000000000000000"),12,1)&" ribu ")&IF(--MID(TEXT(ABS(E37),"000000000000000"),13,3)=0,"",MID(TEXT(ABS(E37),"000000000000000"),13,1)&" ratus "&MID(TEXT(ABS(E37),"000000000000000"),14,1)&" puluh "&MID(TEXT(ABS(E37),"000000000000000"),15,1)),1,"satu"),2,"dua"),3,"tiga"),4,"empat"),5,"lima"),6,"enam"),7,"tujuh"),8,"delapan"),9,"sembilan"),"0 ratus",""),"0 puluh",""),"satu puluh 0","sepuluh"),"satu puluh satu","sebelas"),"satu puluh dua","duabelas"),"satu puluh tiga","tigabelas"),"satu puluh empat","empatbelas"),"satu puluh lima","limabelas"),"satu puluh enam","enambelas"),"satu puluh tujuh","tujuhbelas"),"satu puluh delapan","delapanbelas"),"satu puluh sembilan","sembilanbelas"),"satu ratus","seratus"),"*satu ribu","seribu"),0,""))," "," "))&" Rupiah") -> Delapan Ratus Lima Puluh Ribu Rupiah
I41: Banjarmasin, 06 Januari 2026
A42: MENGETAHUI | I42: YANG MEMBUAT
A47: IRNA WAHYUNI N. | I47: M. ZULKIFLI
A56: NOTA PENCAIRAN DANA (NPD)
A57: Nomor : 15/DIV-KEU/PPB/I/2026
A58: BENDAHARA PENGELUARAN
A59: PERUMDA PASAR BANJARMASIN
A60: Supaya Mencairkan Dana
A62: 1. Sub Kegiatan | D62: : | E62: Beban Operasional dan Bisnis
A63: 2. Nomor | D63: : | E63: 2.1.3
A64: 3. Tahun Anggaran | D64: : | E64: 2026
A65: 4. Jumlah Yang Diminta | D65: : | E65: =I78 -> 935000
D66: : | E66: =PROPER(IF(E65=0,"nol",IF(E65<0,"minus ","")&SUBSTITUTE(TRIM(SUBSTITUTE(SUBSTITUTE(SUBSTITUTE(SUBSTITUTE(SUBSTITUTE(SUBSTITUTE(SUBSTITUTE(SUBSTITUTE(SUBSTITUTE(SUBSTITUTE(SUBSTITUTE(SUBSTITUTE(SUBSTITUTE(SUBSTITUTE(SUBSTITUTE(SUBSTITUTE(SUBSTITUTE(SUBSTITUTE(SUBSTITUTE(SUBSTITUTE(SUBSTITUTE(SUBSTITUTE(SUBSTITUTE(SUBSTITUTE(IF(--MID(TEXT(ABS(E65),"000000000000000"),1,3)=0,"",MID(TEXT(ABS(E65),"000000000000000"),1,1)&" ratus "&MID(TEXT(ABS(E65),"000000000000000"),2,1)&" puluh "&MID(TEXT(ABS(E65),"000000000000000"),3,1)&" trilyun ")&IF(--MID(TEXT(ABS(E65),"000000000000000"),4,3)=0,"",MID(TEXT(ABS(E65),"000000000000000"),4,1)&" ratus "&MID(TEXT(ABS(E65),"000000000000000"),5,1)&" puluh "&MID(TEXT(ABS(E65),"000000000000000"),6,1)&" milyar ")&IF(--MID(TEXT(ABS(E65),"000000000000000"),7,3)=0,"",MID(TEXT(ABS(E65),"000000000000000"),7,1)&" ratus "&MID(TEXT(ABS(E65),"000000000000000"),8,1)&" puluh "&MID(TEXT(ABS(E65),"000000000000000"),9,1)&" juta ")&IF(--MID(TEXT(ABS(E65),"000000000000000"),10,3)=0,"",IF(--MID(TEXT(ABS(E65),"000000000000000"),10,3)=1,"*",MID(TEXT(ABS(E65),"000000000000000"),10,1)&" ratus "&MID(TEXT(ABS(E65),"000000000000000"),11,1)&" puluh ")&MID(TEXT(ABS(E65),"000000000000000"),12,1)&" ribu ")&IF(--MID(TEXT(ABS(E65),"000000000000000"),13,3)=0,"",MID(TEXT(ABS(E65),"000000000000000"),13,1)&" ratus "&MID(TEXT(ABS(E65),"000000000000000"),14,1)&" puluh "&MID(TEXT(ABS(E65),"000000000000000"),15,1)),1,"satu"),2,"dua"),3,"tiga"),4,"empat"),5,"lima"),6,"enam"),7,"tujuh"),8,"delapan"),9,"sembilan"),"0 ratus",""),"0 puluh",""),"satu puluh 0","sepuluh"),"satu puluh satu","sebelas"),"satu puluh dua","duabelas"),"satu puluh tiga","tigabelas"),"satu puluh empat","empatbelas"),"satu puluh lima","limabelas"),"satu puluh enam","enambelas"),"satu puluh tujuh","tujuhbelas"),"satu puluh delapan","delapanbelas"),"satu puluh sembilan","sembilanbelas"),"satu ratus","seratus"),"*satu ribu","seribu"),0,""))," "," "))&" Rupiah") -> Sembilan Ratus Tiga Puluh Lima Ribu Rupiah
A69: Pembebanan Pada Kode Rekening
...

Sheet FEBRUARI
A8: NOTA PENCAIRAN DANA (NPD)
A9: Nomor : 071/DIV-KEU/PPB/II/2026
A10: BENDAHARA PENGELUARAN
A11: PERUMDA PASAR BANJARMASIN
A12: Supaya Mencairkan Dana
A14: 1. Sub Kegiatan | D14: : | E14: Beban Operasional dan Bisnis
A15: 2. Nomor | D15: : | E15: 2.1.3
A16: 3. Tahun Anggaran | D16: : | E16: 2026
A17: 4. Jumlah Yang Diminta | D17: : | E17: =I30 -> 860000
D18: : | E18: =PROPER(IF(E17=0,"nol",IF(E17<0,"minus ","")&SUBSTITUTE(TRIM(SUBSTITUTE(SUBSTITUTE(SUBSTITUTE(SUBSTITUTE(SUBSTITUTE(SUBSTITUTE(SUBSTITUTE(SUBSTITUTE(SUBSTITUTE(SUBSTITUTE(SUBSTITUTE(SUBSTITUTE(SUBSTITUTE(SUBSTITUTE(SUBSTITUTE(SUBSTITUTE(SUBSTITUTE(SUBSTITUTE(SUBSTITUTE(SUBSTITUTE(SUBSTITUTE(SUBSTITUTE(SUBSTITUTE(SUBSTITUTE(IF(--MID(TEXT(ABS(E17),"000000000000000"),1,3)=0,"",MID(TEXT(ABS(E17),"000000000000000"),1,1)&" ratus "&MID(TEXT(ABS(E17),"000000000000000"),2,1)&" puluh "&MID(TEXT(ABS(E17),"000000000000000"),3,1)&" trilyun ")&IF(--MID(TEXT(ABS(E17),"000000000000000"),4,3)=0,"",MID(TEXT(ABS(E17),"000000000000000"),4,1)&" ratus "&MID(TEXT(ABS(E17),"000000000000000"),5,1)&" puluh "&MID(TEXT(ABS(E17),"000000000000000"),6,1)&" milyar ")&IF(--MID(TEXT(ABS(E17),"000000000000000"),7,3)=0,"",MID(TEXT(ABS(E17),"000000000000000"),7,1)&" ratus "&MID(TEXT(ABS(E17),"000000000000000"),8,1)&" puluh "&MID(TEXT(ABS(E17),"000000000000000"),9,1)&" juta ")&IF(--MID(TEXT(ABS(E17),"000000000000000"),10,3)=0,"",IF(--MID(TEXT(ABS(E17),"000000000000000"),10,3)=1,"*",MID(TEXT(ABS(E17),"000000000000000"),10,1)&" ratus "&MID(TEXT(ABS(E17),"000000000000000"),11,1)&" puluh ")&MID(TEXT(ABS(E17),"000000000000000"),12,1)&" ribu ")&IF(--MID(TEXT(ABS(E17),"000000000000000"),13,3)=0,"",MID(TEXT(ABS(E17),"000000000000000"),13,1)&" ratus "&MID(TEXT(ABS(E17),"000000000000000"),14,1)&" puluh "&MID(TEXT(ABS(E17),"000000000000000"),15,1)),1,"satu"),2,"dua"),3,"tiga"),4,"empat"),5,"lima"),6,"enam"),7,"tujuh"),8,"delapan"),9,"sembilan"),"0 ratus",""),"0 puluh",""),"satu puluh 0","sepuluh"),"satu puluh satu","sebelas"),"satu puluh dua","duabelas"),"satu puluh tiga","tigabelas"),"satu puluh empat","empatbelas"),"satu puluh lima","limabelas"),"satu puluh enam","enambelas"),"satu puluh tujuh","tujuhbelas"),"satu puluh delapan","delapanbelas"),"satu puluh sembilan","sembilanbelas"),"satu ratus","seratus"),"*satu ribu","seribu"),0,""))," "," "))&" Rupiah") -> Delapan Ratus Enam Puluh Ribu Rupiah
A21: Pembebanan Pada Kode Rekening
A22: NO | C22: Uraian | G22: Anggaran | H22: Akumulasi Pencairan dana Bulan Lalu | I22: Pencairan Saat ini | J22: Sisa Anggaran
A23: 1 | C23: Kelengkapan Pegawai | G23: --------------- | H23: --------------- | I23: --------------- | J23: ---------------
B24: 1.1 | C24: Atribut Petugas Penagihan (Rompi + Tas) | G24: 10000000 | H24: =JANUARI!H120+JANUARI!I120 -> 0 | I24: 0 | J24: =G24-H24-I24 -> 10000000
B25: 1.2 | C25: Baju Petugas Kebersihan | G25: 28600000 | H25: =JANUARI!H121+JANUARI!I121 -> 0 | I25: 860000 | J25: =G25-H25-I25 -> 27740000
B26: 1.3 | C26: Atribut Petugas Kebersihan (Sepatu Booth + Jas Hujan + Rompi Scotlight) | G26: 20000000 | H26: =JANUARI!H122+JANUARI!I122 -> 1785000 | I26: 0 | J26: =G26-H26-I26 -> 18215000
B27: 1.4 | C27: Cetak ID Card + Pin Perumda | G27: 3000000 | H27: =JANUARI!H123+JANUARI!I123 -> 30000 | I27: 0 | J27: =G27-H27-I27 -> 2970000
B28: 1.5 | C28: Atribut Petugas Parkir (Baju + Topi) | G28: 15000000 | H28: =JANUARI!H124+JANUARI!I124 -> 0 | I28: 0 | J28: =G28-H28-I28 -> 15000000
B29: 1.6 | C29: Atribut Petugas Keamanan (29) | G29: 28175000 | H29: =JANUARI!H125+JANUARI!I125 -> 0 | I29: 0 | J29: =G29-H29-I29 -> 28175000
C30: JUMLAH | G30: =SUM(G23:G29) -> 104775000 | H30: =SUM(H23:H27) -> 1815000 | I30: =SUM(I23:I27) -> 860000 | J30: =SUM(J23:K29) -> 102100000
A32: Jumlah Yang Diminta | D32: : | E32: =I30 -> 860000
A33: PPN | D33: :
A34: PPh Psl 21/22/23/4(2) | D34: :
A35: Jumlah Potongan | D35: : | E35: =E33+E34 -> 0
A37: Jumlah yang dibayarkan | D37: : | E37: =E32-E35 -> 860000
E38: =PROPER(IF(E37=0,"nol",IF(E37<0,"minus ","")&SUBSTITUTE(TRIM(SUBSTITUTE(SUBSTITUTE(SUBSTITUTE(SUBSTITUTE(SUBSTITUTE(SUBSTITUTE(SUBSTITUTE(SUBSTITUTE(SUBSTITUTE(SUBSTITUTE(SUBSTITUTE(SUBSTITUTE(SUBSTITUTE(SUBSTITUTE(SUBSTITUTE(SUBSTITUTE(SUBSTITUTE(SUBSTITUTE(SUBSTITUTE(SUBSTITUTE(SUBSTITUTE(SUBSTITUTE(SUBSTITUTE(SUBSTITUTE(IF(--MID(TEXT(ABS(E37),"000000000000000"),1,3)=0,"",MID(TEXT(ABS(E37),"000000000000000"),1,1)&" ratus "&MID(TEXT(ABS(E37),"000000000000000"),2,1)&" puluh "&MID(TEXT(ABS(E37),"000000000000000"),3,1)&" trilyun ")&IF(--MID(TEXT(ABS(E37),"000000000000000"),4,3)=0,"",MID(TEXT(ABS(E37),"000000000000000"),4,1)&" ratus "&MID(TEXT(ABS(E37),"000000000000000"),5,1)&" puluh "&MID(TEXT(ABS(E37),"000000000000000"),6,1)&" milyar ")&IF(--MID(TEXT(ABS(E37),"000000000000000"),7,3)=0,"",MID(TEXT(ABS(E37),"000000000000000"),7,1)&" ratus "&MID(TEXT(ABS(E37),"000000000000000"),8,1)&" puluh "&MID(TEXT(ABS(E37),"000000000000000"),9,1)&" juta ")&IF(--MID(TEXT(ABS(E37),"000000000000000"),10,3)=0,"",IF(--MID(TEXT(ABS(E37),"000000000000000"),10,3)=1,"*",MID(TEXT(ABS(E37),"000000000000000"),10,1)&" ratus "&MID(TEXT(ABS(E37),"000000000000000"),11,1)&" puluh ")&MID(TEXT(ABS(E37),"000000000000000"),12,1)&" ribu ")&IF(--MID(TEXT(ABS(E37),"000000000000000"),13,3)=0,"",MID(TEXT(ABS(E37),"000000000000000"),13,1)&" ratus "&MID(TEXT(ABS(E37),"000000000000000"),14,1)&" puluh "&MID(TEXT(ABS(E37),"000000000000000"),15,1)),1,"satu"),2,"dua"),3,"tiga"),4,"empat"),5,"lima"),6,"enam"),7,"tujuh"),8,"delapan"),9,"sembilan"),"0 ratus",""),"0 puluh",""),"satu puluh 0","sepuluh"),"satu puluh satu","sebelas"),"satu puluh dua","duabelas"),"satu puluh tiga","tigabelas"),"satu puluh empat","empatbelas"),"satu puluh lima","limabelas"),"satu puluh enam","enambelas"),"satu puluh tujuh","tujuhbelas"),"satu puluh delapan","delapanbelas"),"satu puluh sembilan","sembilanbelas"),"satu ratus","seratus"),"*satu ribu","seribu"),0,""))," "," "))&" Rupiah") -> Delapan Ratus Enam Puluh Ribu Rupiah
I41: Banjarmasin, 18 Februari 2026
A42: MENGETAHUI | I42: YANG MEMBUAT
A47: IRNA WAHYUNI N. | I47: M. ZULKIFLI
A56: NOTA PENCAIRAN DANA (NPD)
A57: Nomor : 084/DIV-KEU/PPB/II/2026
A58: BENDAHARA PENGELUARAN
A59: PERUMDA PASAR BANJARMASIN
A60: Supaya Mencairkan Dana
A62: 1. Sub Kegiatan | D62: : | E62: Beban Operasional dan Bisnis
A63: 2. Nomor | D63: : | E63: 2.1.3
A64: 3. Tahun Anggaran | D64: : | E64: 2026
A65: 4. Jumlah Yang Diminta | D65: : | E65: =I78 -> 2200000
D66: : | E66: =PROPER(IF(E65=0,"nol",IF(E65<0,"minus ","")&SUBSTITUTE(TRIM(SUBSTITUTE(SUBSTITUTE(SUBSTITUTE(SUBSTITUTE(SUBSTITUTE(SUBSTITUTE(SUBSTITUTE(SUBSTITUTE(SUBSTITUTE(SUBSTITUTE(SUBSTITUTE(SUBSTITUTE(SUBSTITUTE(SUBSTITUTE(SUBSTITUTE(SUBSTITUTE(SUBSTITUTE(SUBSTITUTE(SUBSTITUTE(SUBSTITUTE(SUBSTITUTE(SUBSTITUTE(SUBSTITUTE(SUBSTITUTE(IF(--MID(TEXT(ABS(E65),"000000000000000"),1,3)=0,"",MID(TEXT(ABS(E65),"000000000000000"),1,1)&" ratus "&MID(TEXT(ABS(E65),"000000000000000"),2,1)&" puluh "&MID(TEXT(ABS(E65),"000000000000000"),3,1)&" trilyun ")&IF(--MID(TEXT(ABS(E65),"000000000000000"),4,3)=0,"",MID(TEXT(ABS(E65),"000000000000000"),4,1)&" ratus "&MID(TEXT(ABS(E65),"000000000000000"),5,1)&" puluh "&MID(TEXT(ABS(E65),"000000000000000"),6,1)&" milyar ")&IF(--MID(TEXT(ABS(E65),"000000000000000"),7,3)=0,"",MID(TEXT(ABS(E65),"000000000000000"),7,1)&" ratus "&MID(TEXT(ABS(E65),"000000000000000"),8,1)&" puluh "&MID(TEXT(ABS(E65),"000000000000000"),9,1)&" juta ")&IF(--MID(TEXT(ABS(E65),"000000000000000"),10,3)=0,"",IF(--MID(TEXT(ABS(E65),"000000000000000"),10,3)=1,"*",MID(TEXT(ABS(E65),"000000000000000"),10,1)&" ratus "&MID(TEXT(ABS(E65),"000000000000000"),11,1)&" puluh ")&MID(TEXT(ABS(E65),"000000000000000"),12,1)&" ribu ")&IF(--MID(TEXT(ABS(E65),"000000000000000"),13,3)=0,"",MID(TEXT(ABS(E65),"000000000000000"),13,1)&" ratus "&MID(TEXT(ABS(E65),"000000000000000"),14,1)&" puluh "&MID(TEXT(ABS(E65),"000000000000000"),15,1)),1,"satu"),2,"dua"),3,"tiga"),4,"empat"),5,"lima"),6,"enam"),7,"tujuh"),8,"delapan"),9,"sembilan"),"0 ratus",""),"0 puluh",""),"satu puluh 0","sepuluh"),"satu puluh satu","sebelas"),"satu puluh dua","duabelas"),"satu puluh tiga","tigabelas"),"satu puluh empat","empatbelas"),"satu puluh lima","limabelas"),"satu puluh enam","enambelas"),"satu puluh tujuh","tujuhbelas"),"satu puluh delapan","delapanbelas"),"satu puluh sembilan","sembilanbelas"),"satu ratus","seratus"),"*satu ribu","seribu"),0,""))," "," "))&" Rupiah") -> Dua Juta Dua Ratus Ribu Rupiah
A69: Pembebanan Pada Kode Rekening
...
